Workbook

Sheet ADM
A1: Análise de indicadores | C1: Jan | D1: Fev | E1: Mar | F1: Abr | G1: Mai | H1: Jun | I1: Jul | J1: Ago | K1: Set | L1: Out | M1: Nov | N1: Dez | O1: Total
A2: Efetivo Inicial (Un) | C2: 3 | D2: 3 | E2: 3 | F2: 3 | G2: 3 | H2: 3 | I2: 3 | J2: 4 | K2: 3 | L2: 5 | M2: 6 | N2: 5 | O2: 3.6666667
A3: Afastamentos + Faltas (dias) | C3: 0 | D3: 5 | E3: 0 | F3: 2 | G3: 0 | H3: 0 | I3: 6 | J3: 2 | K3: 1 | L3: 2 | M3: 3 | N3: 1 | O3: 1.8333333
A4: Novas Contratações (Un) | C4: 0 | D4: 0 | E4: 0 | F4: 0 | G4: 1 | H4: 0 | I4: 1 | J4: 0 | K4: 2 | L4: 1 | M4: 0 | N4: 1 | O4: 0.5
A5: Desligamentos (Un) | C5: 0 | D5: 0 | E5: 0 | F5: 0 | G5: 1 | H5: 0 | I5: 0 | J5: 1 | K5: 0 | L5: 0 | M5: 1 | N5: 1 | O5: 0.33333333
A6: Efetivo Final (Un) | C6: 3 | D6: 3 | E6: 3 | F6: 3 | G6: 3 | H6: 3 | I6: 4 | J6: 3 | K6: 5 | L6: 6 | M6: 5 | N6: 5 | O6: 3.8333333
A7: Efetivo Médio | C7: 3 | D7: 3 | E7: 3 | F7: 3 | G7: 3 | H7: 3 | I7: 3.5 | J7: 3.5 | K7: 4 | L7: 5.5 | M7: 5.5 | N7: 5 | O7: 3.75
A8: Férias (dias não produtivos) | C8: 5 | D8: 0 | E8: 5 | F8: 0 | G8: 0 | H8: 0 | I8: 0 | J8: 0 | K8: 0 | L8: 0 | M8: 0 | N8: 0 | O8: 0.83333333
A9: Colaboradores de Férias (Un) | C9: 1 | D9: 0 | E9: 1 | F9: 0 | G9: 0 | H9: 0 | I9: 0 | J9: 0 | K9: 0 | L9: 0 | M9: 0 | N9: 0 | O9: 0.16666667
A10: Dias Úteis | C10: 22 | D10: 21 | E10: 20 | F10: 21 | G10: 21 | H10: 20 | I10: 23 | J10: 22 | K10: 21 | L10: 23 | M10: 21 | N10: 21 | O10: 21.333333
A11: Dias Programados | C11: 66 | D11: 63 | E11: 60 | F11: 63 | G11: 63 | H11: 60 | I11: 80.5 | J11: 77 | K11: 84 | L11: 126.5 | M11: 115.5 | N11: 105 | O11: 80.291667
A12: Dias Produtivos | C12: 61 | D12: 63 | E12: 55 | F12: 63 | G12: 63 | H12: 60 | I12: 80.5 | J12: 77 | K12: 84 | L12: 126.5 | M12: 115.5 | N12: 105 | O12: 79.458333
A13: Dias não Produtivos | C13: 5 | D13: 5 | E13: 5 | F13: 2 | G13: 0 | H13: 0 | I13: 6 | J13: 2 | K13: 1 | L13: 2 | M13: 3 | N13: 1 | O13: 2.6666667
... A21: Salário Per Capto (R$) | C21: 2671.0667 | D21: 2671.0667 | E21: 2671.0667 | F21: 2671.0667 | G21: 2664.7967 | H21: 2837.7333 | I21: 2600.3429 | J21: 2574.8571 | K21: 3293.3325 | L21: 3184.1782 | M21: 2620.3636 | N21: 2829.066 | O21: 2774.0781
A22: Valor de Tributos | C22: =#REF! -> #REF! | D22: =#REF! -> #REF! | E22: =#REF! -> #REF! | F22: =#REF! -> #REF! | G22: 481.42 | H22: =#REF! -> #REF! | I22: =#REF! -> #REF! | J22: =#REF! -> #REF! | K22: =#REF! -> #REF! | L22: =#REF! -> #REF! | M22: 1040 | N22: 1040 | O22: =#REF! -> #REF!
A23: INSS Patronal | O23: 0
A24: FGTS | C24: =#REF! -> #REF! | D24: =#REF! -> #REF! | E24: =#REF! -> #REF! | F24: =#REF! -> #REF! | G24: 481.42 | H24: =#REF! -> #REF! | I24: =#REF! -> #REF! | J24: =#REF! -> #REF! | K24: =#REF! -> #REF! | L24: =#REF! -> #REF! | M24: 1040 | N24: 1040 | O24: =#REF! -> #REF!
A25: Encargos sobre a Folha (%) | G25: 0.060219729 | M25: 0.072162087 | N25: 0.073522498 | O25: 0.017158693

Sheet ADM 2025
A1: Análise de indicadores | C1: Jan | D1: Fev | E1: Mar | F1: Abr | G1: Mai | H1: Jun | I1: Jul | J1: Ago | K1: Set | L1: Out | M1: Nov | N1: Dez | O1: Total
A2: Efetivo Inicial (Un) | C2: 5 | D2: 6 | E2: 6 | F2: 6 | G2: 6 | H2: 6 | I2: 4 | J2: 5 | K2: 5 | L2: 4 | M2: 4 | N2: 4 | O2: =AVERAGE(C2:N2) -> 5.0833333
A3: Afastamentos + Faltas (dias) | C3: 3 | D3: 0 | E3: 1 | F3: 0 | G3: 5 | H3: 0 | I3: 0 | J3: 0 | K3: 0 | L3: 0 | M3: 0 | N3: 0 | O3: =AVERAGE(C3:N3) -> 0.75
A4: Novas Contratações (Un) | C4: 1 | D4: 2 | E4: 2 | F4: 1 | G4: 0 | H4: 0 | I4: 1 | J4: 0 | K4: 0 | L4: 0 | M4: 1 | N4: 1 | O4: =AVERAGE(C4:N4) -> 0.75
A5: Desligamentos (Un) | C5: 0 | D5: 2 | E5: 2 | F5: 1 | G5: 0 | H5: 2 | I5: 0 | J5: 0 | K5: 1 | L5: 0 | M5: 1 | N5: 2 | O5: =AVERAGE(C5:N5) -> 0.91666667
A6: Efetivo Final (Un) | C6: =C2+C4-C5 -> 6 | D6: =D2+D4-D5 -> 6 | E6: =E2+E4-E5 -> 6 | F6: =F2+F4-F5 -> 6 | G6: =G2+G4-G5 -> 6 | H6: =H2+H4-H5 -> 4 | I6: =I2+I4-I5 -> 5 | J6: =J2+J4-J5 -> 5 | ... N6: =N2+N4-N5 -> 3 | O6: =AVERAGE(C6:N6) -> 4.9166667
A7: Efetivo Médio | C7: =(C2+C6)/2 -> 5.5 | D7: =(D2+D6)/2 -> 6 | E7: =(E2+E6)/2 -> 6 | F7: =(F2+F6)/2 -> 6 | G7: =(G2+G6)/2 -> 6 | H7: =(H2+H6)/2 -> 5 | I7: =(I2+I6)/2 -> 4.5 | J7: =(J2+J6)/2 -> 5 | ... N7: =(N2+N6)/2 -> 3.5 | O7: =AVERAGE(C7:N7) -> 5
A8: Férias (dias não produtivos) | C8: ='Janeiro 25'!U15 -> 0 | D8: 0 | E8: 0 | F8: 0 | G8: 0 | H8: 0 | I8: 0 | J8: 0 | K8: 0 | L8: 13 | M8: 0 | N8: 0 | O8: =AVERAGE(C8:N8) -> 1.0833333
A9: Colaboradores de Férias (Un) | C9: ='Janeiro 25'!U16 -> 0 | D9: 0 | E9: 0 | F9: 0 | G9: 0 | H9: 0 | I9: 0 | J9: 0 | K9: 0 | L9: 1 | M9: 0 | N9: 0 | O9: =AVERAGE(C9:N9) -> 0.083333333
A10: Dias Úteis | C10: =#REF! -> #REF! | D10: 20 | E10: 21 | F10: 19 | G10: 20 | H10: 20 | I10: 23 | J10: 21 | K10: 22 | L10: 23 | M10: 21 | N10: 22 | O10: =AVERAGE(C10:N10) -> #REF!
A11: Dias Programados | C11: =C10*C7 -> #REF! | D11: =D10*D7 -> 120 | E11: =E10*E7 -> 126 | F11: =F10*F7 -> 114 | G11: =G10*G7 -> 120 | H11: =H10*H7 -> 100 | I11: =I10*I7 -> 103.5 | J11: =J10*J7 -> 105 | ... N11: =N10*N7 -> 77 | O11: =AVERAGE(C11:N11) -> #REF!
A12: Dias Produtivos | C12: =C11-(C8+C3) -> #REF! | D12: =D11-(D8+D3) -> 120 | E12: =E11-(E8+E3) -> 125 | F12: =F11-(F8+F3) -> 114 | G12: =G11-(G8+G3) -> 115 | H12: =H11-(H8+H3) -> 100 | I12: =I11-(I8+I3) -> 103.5 | J12: =J11-(J8+J3) -> 105 | ... N12: =N11-(N8+N3) -> 77 | O12: =AVERAGE(C12:N12) -> #REF!
A13: Dias não Produtivos | C13: =C8+C3 -> 3 | D13: =D8+D3 -> 0 | E13: =E8+E3 -> 1 | F13: =F8+F3 -> 0 | G13: =G8+G3 -> 5 | H13: =H8+H3 -> 0 | I13: =I8+I3 -> 0 | J13: =J8+J3 -> 0 | ... N13: =N8+N3 -> 0 | O13: =AVERAGE(C13:N13) -> 1.8333333
A14: Horas Programadas | C14: =(C6*8.8)*C10 -> #REF! | D14: =(D6*8.8)*D10 -> 1056 | E14: =(E6*8.8)*E10 -> 1108.8 | F14: =(F6*8.8)*F10 -> 1003.2 | G14: =(G6*8.8)*G10 -> 1056 | H14: =(H6*8.8)*H10 -> 704 | I14: =(I6*8.8)*I10 -> 1012 | J14: =(J6*8.8)*J10 -> 924 | ... N14: =(N6*8.8)*N10 -> 580.8 | O14: =AVERAGE(C14:N14) -> #REF!
A15: Horas não Produtivas | C15: =C13*8.8 -> 26.4 | D15: =D13*8.8 -> 0 | E15: =E13*8.8 -> 8.8 | F15: =F13*8.8 -> 0 | G15: =G13*8.8 -> 44 | H15: =H13*8.8 -> 0 | I15: =I13*8.8 -> 0 | J15: =J13*8.8 -> 0 | ... N15: =N13*8.8 -> 0 | O15: =AVERAGE(C15:N15) -> 16.133333
A16: Efetivo Pessoal Mês | C16: =(C14-C15)/(8.8*C10) -> #REF! | D16: =(D14-D15)/(8.8*D10) -> 6 | E16: =(E14-E15)/(8.8*E10) -> 5.952381 | F16: =(F14-F15)/(8.8*F10) -> 6 | G16: =(G14-G15)/(8.8*G10) -> 5.75 | H16: =(H14-H15)/(8.8*H10) -> 4 | I16: =(I14-I15)/(8.8*I10) -> 5 | J16: =(J14-J15)/(8.8*J10) -> 5 | ... N16: =(N14-N15)/(8.8*N10) -> 3 | O16: =AVERAGE(C16:N16) -> #REF!
A17: Taxa de Absenteísmo | C17: =IFERROR((C15/C14),"") | D17: =IFERROR((D15/D14),"") -> 0 | E17: =IFERROR((E15/E14),"") -> 0.0079365079 | F17: =IFERROR((F15/F14),"") -> 0 | G17: =IFERROR((G15/G14),"") -> 0.041666667 | H17: =IFERROR((H15/H14),"") -> 0 | I17: =IFERROR((I15/I14),"") -> 0 | J17: =IFERROR((J15/J14),"") -> 0 | ... N17: =IFERROR((N15/N14),"") -> 0 | O17: =SUM(C17:N17)/12 -> 0.01590896
A18: Taxa de Turnover | C18: =IFERROR((((C5+C4)/2)/C2),"") -> 0.1 | D18: =IFERROR((((D5+D4)/2)/D2),"") -> 0.33333333 | E18: =IFERROR((((E5+E4)/2)/E2),"") -> 0.33333333 | F18: =IFERROR((((F5+F4)/2)/F2),"") -> 0.16666667 | G18: =IFERROR((((G5+G4)/2)/G2),"") -> 0 | H18: =IFERROR((((H5+H4)/2)/H2),"") -> 0.16666667 | I18: =IFERROR((((I5+I4)/2)/I2),"") -> 0.125 | J18: =IFERROR((((J5+J4)/2)/J2),"") -> 0 | ... N18: =IFERROR((((N5+N4)/2)/N2),"") -> 0.375 | O18: =SUM(C18:N18)/12 -> 0.1625
A19: Folha Líquida (R$) | C19: ='Fopag Analitic'!D15 -> 13226.01 | D19: ='Fopag Analitic'!G15 -> 13130.21 | E19: ='Fopag Analitic'!J15 -> 11749.71 | F19: ='Fopag Analitic'!M15 -> 13076.92 | G19: ='Fopag Analitic'!P15 -> 14689.69 | H19: 10094.15 | I19: 12554.18 | J19: 14081.11 | K19: 11783.34 | L19: 9549.1 | M19: =11333.06+4679.17 -> 16012.23 | O19: =SUM(C19:N19) -> 139946.65
A20: Folha Bruta (R$) | C20: ='Fopag Analitic'!D14 -> 14480 | D20: ='Fopag Analitic'!G14 -> 14300 | E20: ='Fopag Analitic'!J14 -> 12800 | F20: ='Fopag Analitic'!M14 -> 14320 | G20: ='Fopag Analitic'!P14 -> 16000 | H20: 11000 | I20: 13733.33 | J20: 15400 | K20: 12900 | L20: 12900 | M20: =12700+4679.17 -> 17379.17 | O20: =SUM(C20:N20) -> 155212.5
A21: Salário Per Capto (R$) | C21: =IFERROR((C20/C7),"") -> 2632.7273 | D21: =IFERROR((D20/D7),"") -> 2383.3333 | E21: =IFERROR((E20/E7),"") -> 2133.3333 | F21: =IFERROR((F20/F7),"") -> 2386.6667 | G21: =IFERROR((G20/G7),"") -> 2666.6667 | H21: =IFERROR((H20/H7),"") -> 2200 | I21: =IFERROR((I20/I7),"") -> 3051.8511 | J21: =IFERROR((J20/J7),"") -> 3080 | ... M21: =IFERROR((M20/M7),"") -> 4344.7925 | O21: {=SUM(C21:N21/12)} -> 2580.9198
A22: Valor de Tributos | C22: =SUM(C23:C25) -> 4899.64 | D22: =SUM(D23:D25) -> 4836.1 | E22: =SUM(E23:E25) -> 4306.6 | F22: =SUM(F23:F25) -> 4843.16 | G22: =SUM(G23:G25) -> 5436.2 | H22: =SUM(H23:H25) -> 3671.2 | I22: =SUM(I23:I25) -> 4636.0655 | J22: =SUM(J23:J25) -> 5995 | ... M22: =SUM(M23:M25) -> 2122.33 | O22: =SUM(C22:N22) -> 50912.095
A23: INSS Patronal | O23: =SUM(C23:N23) -> 0
A24: FGTS | C24: ='Fopag Analitic'!D17 -> 1110.4 | D24: ='Fopag Analitic'!G17 -> 1096 | E24: ='Fopag Analitic'!J17 -> 976 | F24: ='Fopag Analitic'!M17 -> 1097.6 | G24: ='Fopag Analitic'!P17 -> 1232 | H24: ='Fopag Analitic'!S17 -> 832 | I24: ='Fopag Analitic'!V17 -> 1050.6664 | J24: 1184 | K24: 984 | L24: 924 | M24: =968+374.33 -> 1342.33 | O24: =SUM(C24:N24) -> 11828.996
A25: INSS Patronal | C25: ='Fopag Analitic'!D18+'Fopag Analitic'!D19+'Fopag Analitic'!D20 -> 3789.24 | D25: ='Fopag Analitic'!G18+'Fopag Analitic'!G19+'Fopag Analitic'!G20 -> 3740.1 | E25: ='Fopag Analitic'!J18+'Fopag Analitic'!J19+'Fopag Analitic'!J20 -> 3330.6 | F25: ='Fopag Analitic'!M18+'Fopag Analitic'!M19+'Fopag Analitic'!M20 -> 3745.56 | G25: ='Fopag Analitic'!P18+'Fopag Analitic'!P19+'Fopag Analitic'!P20 -> 4204.2 | H25: ='Fopag Analitic'!S18+'Fopag Analitic'!S19+'Fopag Analitic'!S20 -> 2839.2 | I25: ='Fopag Analitic'!V18+'Fopag Analitic'!V19+'Fopag Analitic'!V20 -> 3585.3991 | J25: 4811 | K25: 4128.9 | L25: 4128.9 | M25: ='Fopag 01 26'!B32 -> 780 | O25: =SUM(C25:N25) -> 39083.099
A26: Encargos sobre a Folha (%) | C26: =IFERROR((C22/C20),"") -> 0.33837293 | D26: =IFERROR((D22/D20),"") -> 0.33818881 | E26: =IFERROR((E22/E20),"") -> 0.33645313 | F26: =IFERROR((F22/F20),"") -> 0.3382095 | G26: =IFERROR((G22/G20),"") -> 0.3397625 | H26: =IFERROR((H22/H20),"") -> 0.33374545 | I26: =IFERROR((I22/I20),"") -> 0.33757767 | J26: =IFERROR((J22/J20),"") -> 0.38928571 | ... N26: =IFERROR((N22/N20),"") | O26: =SUM(C26:N26)/12 -> 0.30514678

Sheet Jan
H1: Atestados | M1: Faltas | O1: Férias
B2: Funcionário | C2: Nome do Funcionário | D2: Departamento | E2: Admissão | F2: Demissão | G2: Afastamento | H2: Início | I2: Fim | J2: Início | K2: Fim | L2: Dias | M2: Faltas | N2: Dias | O2: Início | P2: Fim | Q2: Dias | R2: Observação
B3: 2 | C3: LEANDRO PINHEIRO DOS SANTO | D3: PRODUCAO | E3: 44599 | L3: =(I3-H3) -> 0 | T3: Início Colab | U3: 3
B4: 1 | C4: LUCAS ANDRADE SILVA | D4: PRODUCAO | E4: 44599 | L4: =(I4-H4) -> 0 | T4: Admissão | U4: 0
B5: 3 | C5: SAMY HERCULANO PINTO | D5: PRODUCAO | E5: 44602 | L5: =(I5-H5) -> 0 | O5: 45306 | P5: 45310 | Q5: 5 | T5: Demissão | U5: 0
L6: =SUM(L3:L5) -> 0 | N6: =SUM(N3:N5) -> 0 | Q6: =SUM(Q3:Q5) -> 5 | T6: Fim Colab | U6: =U3+U4-U5 -> 3
T8: Sócio | U8: 2
T9: Total | U9: =U6+U8 -> 5
T11: Afastamentos
T12: Atestados | U12: =L6 -> 0
T13: Faltas | U13: =N6 -> 0
T15: Férias | U15: =Q6 -> 5
T16: Colaboradores | U16: 0
T18: Dias Úteis | U18: 22

Sheet Fev
H1: Atestados | M1: Faltas | O1: Férias
B2: Funcionário | C2: Nome do Funcionário | D2: Departamento | E2: Admissão | F2: Demissão | G2: Afastamento | H2: Início | I2: Fim | J2: Início | K2: Fim | L2: Dias | M2: Faltas | N2: Dias | O2: Início | P2: Fim | Q2: Dias | R2: Observação
B3: 2 | C3: LEANDRO PINHEIRO DOS SANTO | D3: PRODUCAO | E3: 44599 | H3: 45337 | I3: 45338 | L3: 2 | T3: Início Colab | U3: 3
B4: 1 | C4: LUCAS ANDRADE SILVA | D4: PRODUCAO | E4: 44599 | L4: =(I4-H4) -> 0 | T4: Admissão | U4: 0
B5: 3 | C5: SAMY HERCULANO PINTO | D5: PRODUCAO | E5: 44602 | H5: 45343 | I5: 45346 | L5: 3 | T5: Demissão | U5: 0
L6: =SUM(L3:L5) -> 5 | N6: =SUM(N3:N5) -> 0 | Q6: =SUM(Q3:Q5) -> 0 | T6: Fim Colab | U6: =U3+U4-U5 -> 3
T8: Sócio | U8: 2
T9: Total | U9: =U6+U8 -> 5
T11: Afastamentos
T12: Atestados | U12: =L6 -> 5
T13: Faltas | U13: =N6 -> 0
T15: Férias | U15: =Q6 -> 0
T16: Colaboradores | U16: 0
T18: Dias Úteis | U18: 21

Sheet Mar
H1: Atestados | M1: Faltas | O1: Férias
B2: Funcionário | C2: Nome do Funcionário | D2: Departamento | E2: Admissão | F2: Demissão | G2: Afastamento | H2: Início | I2: Fim | J2: Início | K2: Fim | L2: Dias | M2: Faltas | N2: Dias | O2: Início | P2: Fim | Q2: Dias | R2: Observação
B3: 2 | C3: LEANDRO PINHEIRO DOS SANTO | D3: PRODUCAO | E3: 44599 | L3: =(I3-H3) -> 0 | O3: 45369 | P3: 45375 | Q3: 5 | T3: Início Colab | U3: 3
B4: 1 | C4: LUCAS ANDRADE SILVA | D4: PRODUCAO | E4: 44599 | L4: =(I4-H4) -> 0 | T4: Admissão | U4: 0
B5: 3 | C5: SAMY HERCULANO PINTO | D5: PRODUCAO | E5: 44602 | L5: =(I5-H5) -> 0 | T5: Demissão | U5: 0
L6: =SUM(L3:L5) -> 0 | N6: =SUM(N3:N5) -> 0 | Q6: =SUM(Q3:Q5) -> 5 | T6: Fim Colab | U6: =U3+U4-U5 -> 3
T8: Sócio | U8: 2
T9: Total | U9: =U6+U8 -> 5
T11: Afastamentos
T12: Atestados | U12: =L6 -> 0
T13: Faltas | U13: =N6 -> 0
T15: Férias | U15: =Q6 -> 5
T16: Colaboradores | U16: 0
T18: Dias Úteis | U18: 20

Sheet Abril
H1: Atestados | M1: Faltas | O1: Férias
B2: Funcionário | C2: Nome do Funcionário | D2: Departamento | E2: Admissão | F2: Demissão | G2: Afastamento | H2: Início | I2: Fim | J2: Início | K2: Fim | L2: Dias | M2: Faltas | N2: Dias | O2: Início | P2: Fim | Q2: Dias | R2: Observação
B3: 2 | C3: LEANDRO PINHEIRO DOS SANTO | D3: PRODUCAO | E3: 44599 | L3: =(I3-H3) -> 0 | Q3: 0 | T3: Início Colab | U3: 3
B4: 1 | C4: LUCAS ANDRADE SILVA | D4: PRODUCAO | E4: 44599 | L4: =(I4-H4) -> 0 | T4: Admissão | U4: 0
B5: 3 | C5: SAMY HERCULANO PINTO | D5: PRODUCAO | E5: 44602 | H5: 45407 | I5: 45408 | L5: 2 | T5: Demissão | U5: 0
L6: =SUM(L3:L5) -> 2 | N6: =SUM(N3:N5) -> 0 | Q6: =SUM(Q3:Q5) -> 0 | T6: Fim Colab | U6: =U3+U4-U5 -> 3
T8: Sócio | U8: 2
T9: Total | U9: =U6+U8 -> 5
T11: Afastamentos
T12: Atestados | U12: =L6 -> 2
T13: Faltas | U13: =N6 -> 0
T15: Férias | U15: =Q6 -> 0
T16: Colaboradores | U16: 0
T18: Dias Úteis | U18: 20

Sheet Maio
H1: Atestados | M1: Faltas | O1: Férias
B2: Funcionário | C2: Nome do Funcionário | D2: Departamento | E2: Admissão | F2: Demissão | G2: Afastamento | H2: Início | I2: Fim | J2: Início | K2: Fim | L2: Dias | M2: Faltas | N2: Dias | O2: Início | P2: Fim | Q2: Dias | R2: Observação
B3: 2 | C3: LEANDRO PINHEIRO DOS SANTO | D3: ADM | E3: 44599 | L3: =(I3-H3) -> 0 | Q3: 0 | T3: Início Colab | U3: 3
B4: 1 | C4: LUCAS ANDRADE SILVA | D4: ADM | E4: 44599 | F4: 45443 | L4: =(I4-H4) -> 0 | R4: Termino do aviso 31/05/2024 | T4: Admissão | U4: 1
B5: 3 | C5: SAMY HERCULANO PINTO | D5: ADM | E5: 44602 | L5: 0 | T5: Demissão | U5: 1
B6: 4 | C6: GABRIELLY LOPES MACHADO | D6: ADM | E6: 45426 | L6: 0 | T6: Fim Colab | U6: =U3+U4-U5 -> 3
L7: =SUM(L3:L5) -> 0 | N7: =SUM(N3:N5) -> 0 | Q7: =SUM(Q3:Q5) -> 0
T8: Sócio | U8: 2
T9: Total | U9: =U6+U8 -> 5
T11: Afastamentos
T12: Atestados | U12: =L7 -> 0
T13: Faltas | U13: =N7 -> 0
T15: Férias | U15: =Q7 -> 0
T16: Colaboradores | U16: 0
T18: Dias Úteis | U18: 21

Sheet Junho
H1: Atestados | M1: Faltas | O1: Férias
B2: Funcionário | C2: Nome do Funcionário | D2: Departamento | E2: Admissão | F2: Demissão | G2: Afastamento | H2: Início | I2: Fim | J2: Início | K2: Fim | L2: Dias | M2: Faltas | N2: Dias | O2: Início | P2: Fim | Q2: Dias | R2: Observação
B3: 2 | C3: LEANDRO PINHEIRO DOS SANTO | D3: ADM | E3: 44599 | L3: =(I3-H3) -> 0 | Q3: 0 | T3: Início Colab | U3: 3
B4: 3 | C4: SAMY HERCULANO PINTO | D4: ADM | E4: 44602 | L4: 0 | Q4: 0 | T4: Admissão | U4: 0
B5: 4 | C5: GABRIELLY LOPES MACHADO | D5: ADM | E5: 45426 | L5: 0 | Q5: 0 | T5: Demissão | U5: 0
L6: =SUM(L3:L5) -> 0 | N6: =SUM(N3:N4) -> 0 | Q6: =SUM(Q3:Q4) -> 0 | T6: Fim Colab | U6: =U3+U4-U5 -> 3
T8: Sócio | U8: 2
T9: Total | U9: =U6+U8 -> 5
T11: Afastamentos
T12: Atestados | U12: =L6 -> 0
T13: Faltas | U13: =N6 -> 0
T15: Férias | U15: =Q6 -> 0
T16: Colaboradores | U16: 0
T18: Dias Úteis | U18: 20

Sheet Julho
H1: Atestados | M1: Faltas | O1: Férias
B2: Funcionário | C2: Nome do Funcionário | D2: Departamento | E2: Admissão | F2: Demissão | G2: Afastamento | H2: Início | I2: Fim | J2: Início | K2: Fim | L2: Dias | M2: Faltas | N2: Dias | O2: Início | P2: Fim | Q2: Dias | R2: Observação
B3: 2 | C3: LEANDRO PINHEIRO DOS SANTO | D3: ADM | E3: 44599 | L3: =(I3-H3) -> 0 | N3: 0 | Q3: 0 | T3: Início Colab | U3: 3
B4: 3 | C4: SAMY HERCULANO PINTO | D4: ADM | E4: 44602 | L4: 0 | N4: 0 | Q4: 0 | T4: Admissão | U4: 1
B5: 5 | C5: GABRIEL FONSECA DA SILVA | D5: ADM | E5: 45477 | L5: 0 | N5: 0 | Q5: 0 | T5: Demissão | U5: 0
B6: 4 | C6: GABRIELLY LOPES MACHADO | D6: ADM | E6: 45426 | H6: 45498 | I6: 45499 | J6: 45502 | K6: 45504 | L6: 5 | M6: 45483 | N6: 1 | Q6: 0 | T6: Fim Colab | U6: =U3+U4-U5 -> 4
L7: =SUM(L3:L6) -> 5 | N7: =SUM(N3:N6) -> 1 | Q7: =SUM(Q3:Q6) -> 0
T8: Sócio | U8: 2
T9: Total | U9: =U6+U8 -> 6
T11: Afastamentos
T12: Atestados | U12: =L7 -> 5
T13: Faltas | U13: =N7 -> 1
T15: Férias | U15: =Q7 -> 0
T16: Colaboradores | U16: 0
T18: Dias Úteis | U18: 23

Sheet Agosto
H1: Atestados | M1: Faltas | O1: Férias
B2: Funcionário | C2: Nome do Funcionário | D2: Departamento | E2: Admissão | F2: Demissão | G2: Afastamento | H2: Início | I2: Fim | J2: Início | K2: Fim | L2: Dias | M2: Faltas | N2: Dias | O2: Início | P2: Fim | Q2: Dias | R2: Observação
B3: 2 | C3: LEANDRO PINHEIRO DOS SANTO | D3: ADM | E3: 44599 | L3: =(I3-H3) -> 0 | N3: 0 | Q3: 0 | T3: Início Colab | U3: 4
B4: 3 | C4: SAMY HERCULANO PINTO | D4: ADM | E4: 44602 | H4: 45513 | I4: 45513 | L4: 1 | N4: 0 | Q4: 0 | T4: Admissão | U4: 0
B5: 5 | C5: GABRIEL FONSECA DA SILVA | D5: ADM | E5: 45477 | L5: 0 | M5: 45525 | N5: 1 | Q5: 0 | T5: Demissão | U5: 1
B6: 4 | C6: GABRIELLY LOPES MACHADO | D6: ADM | E6: 45426 | L6: 0 | N6: 0 | Q6: 0 | R6: Desligamento 02/08/2024 | T6: Fim Colab | U6: =U3+U4-U5 -> 3
L7: =SUM(L3:L6) -> 1 | N7: =SUM(N3:N6) -> 1 | Q7: =SUM(Q3:Q6) -> 0
T8: Sócio | U8: 2
T9: Total | U9: =U6+U8 -> 5
T11: Afastamentos
T12: Atestados | U12: =L7 -> 1
T13: Faltas | U13: =N7 -> 1
T15: Férias | U15: =Q7 -> 0
T16: Colaboradores | U16: 0
T18: Dias Úteis | U18: 22

Sheet Setembro
H1: Atestados | M1: Faltas | O1: Férias
B2: Funcionário | C2: Nome do Funcionário | D2: Departamento | E2: Admissão | F2: Demissão | G2: Afastamento | H2: Início | I2: Fim | J2: Início | K2: Fim | L2: Dias | M2: Faltas | N2: Dias | O2: Início | P2: Fim | Q2: Dias | R2: Observação
B3: 2 | C3: LEANDRO PINHEIRO DOS SANTO | D3: ADM | E3: 44599 | L3: =(I3-H3) -> 0 | N3: 0 | Q3: 0 | T3: Início Colab | U3: 3
B4: 3 | C4: SAMY HERCULANO PINTO | D4: ADM | E4: 44602 | L4: 0 | N4: 0 | O4: 45544 | P4: 45550 | Q4: 6 | T4: Admissão | U4: 2
B5: 5 | C5: GABRIEL FONSECA DA SILVA | D5: ADM | E5: 45477 | L5: =(I5-H5) -> 0 | N5: 0 | Q5: 0 | T5: Demissão | U5: 0
B6: 6 | C6: MAXSUEL MOREIRA REZENDE | D6: ADM | E6: 45539 | L6: 0 | M6: 45553 | N6: 1 | Q6: 0 | T6: Fim Colab | U6: =U3+U4-U5 -> 5
B7: 7 | C7: AUGUSTO CESAR DA SILVA FILHO | D7: ADM | E7: 45546 | L7: 0 | N7: 0 | Q7: 0
L8: =SUM(L3:L7) -> 0 | N8: =SUM(N3:N7) -> 1 | Q8: =SUM(Q3:Q7) -> 6 | T8: Sócio | U8: 2
T9: Total | U9: =U6+U8 -> 7
T11: Afastamentos
T12: Atestados | U12: =L8 -> 0
T13: Faltas | U13: =N8 -> 1
T15: Férias | U15: =Q8 -> 6
T16: Colaboradores | U16: 0
T18: Dias Úteis | U18: 21

Sheet Outubro
H1: Atestados | M1: Faltas | O1: Férias
B2: Funcionário | C2: Nome do Funcionário | D2: Departamento | E2: Admissão | F2: Demissão | G2: Afastamento | H2: Início | I2: Fim | J2: Início | K2: Fim | L2: Dias | M2: Faltas | N2: Dias | O2: Início | P2: Fim | Q2: Dias | R2: Observação
B3: 7 | C3: AUGUSTO CESAR DA SILVA FILHO | D3: ADM | E3: 45546 | L3: 0 | N3: 0 | Q3: 0 | T3: Início Colab | U3: 5
B4: 5 | C4: GABRIEL FONSECA DA SILVA | D4: ADM | E4: 45477 | L4: =(I4-H4) -> 0 | N4: 0 | Q4: 0 | T4: Admissão | U4: 1
B5: 2 | C5: LEANDRO PINHEIRO DOS SANTO | D5: ADM | E5: 44599 | L5: =(I5-H5) -> 0 | N5: 0 | Q5: 0 | T5: Demissão | U5: 0
B6: 6 | C6: MAXSUEL MOREIRA REZENDE | D6: ADM | E6: 45539 | H6: 45580 | I6: 45581 | L6: 2 | N6: 0 | Q6: 0 | T6: Fim Colab | U6: =U3+U4-U5 -> 6
B7: 8 | C7: RAFAELA REGINA TAMANHONI | D7: ADM | E7: 45567 | L7: 0 | N7: 0 | Q7: 0
B8: 3 | C8: SAMY HERCULANO PINTO | D8: ADM | E8: 44602 | L8: 0 | N8: 0 | Q8: 0 | T8: Sócio | U8: 2
L9: =SUM(L3:L8) -> 2 | N9: =SUM(N3:N8) -> 0 | Q9: =SUM(Q3:Q8) -> 0 | T9: Total | U9: =U6+U8 -> 8
T11: Afastamentos
T12: Atestados | U12: =L9 -> 2
T13: Faltas | U13: =N9 -> 0
T15: Férias | U15: =Q9 -> 0
T16: Colaboradores | U16: 0
T18: Dias Úteis | U18: 23

Sheet Novembro
H1: Atestados | M1: Faltas | O1: Férias
B2: Funcionário | C2: Nome do Funcionário | D2: Departamento | E2: Admissão | F2: Demissão | G2: Afastamento | H2: Início | I2: Fim | J2: Início | K2: Fim | L2: Dias | M2: Faltas | N2: Dias | O2: Início | P2: Fim | Q2: Dias | R2: Observação
B3: 7 | C3: AUGUSTO CESAR DA SILVA FILHO | D3: ADM | E3: 45546 | L3: 0 | N3: 0 | Q3: 0 | T3: Início Colab | U3: 5
B4: 5 | C4: GABRIEL FONSECA DA SILVA | D4: ADM | E4: 45477 | L4: =(I4-H4) -> 0 | N4: 0 | Q4: 0 | T4: Admissão | U4: 0
B5: 2 | C5: LEANDRO PINHEIRO DOS SANTO | D5: ADM | E5: 44599 | L5: =(I5-H5) -> 0 | N5: 0 | Q5: 0 | T5: Demissão | U5: 1
B6: 6 | C6: MAXSUEL MOREIRA REZENDE | D6: ADM | E6: 45539 | F6: 45621 | H6: 45617 | I6: 45618 | L6: 2 | N6: 0 | Q6: 0 | T6: Fim Colab | U6: =U3+U4-U5 -> 4
B7: 8 | C7: RAFAELA REGINA TAMANHONI | D7: ADM | E7: 45567 | H7: 45607 | I7: 45607 | L7: 1 | N7: 0 | Q7: 0
B8: 3 | C8: SAMY HERCULANO PINTO | D8: ADM | E8: 44602 | L8: 0 | N8: 0 | Q8: 0 | T8: Sócio | U8: 2
L9: =SUM(L3:L8) -> 3 | N9: =SUM(N3:N8) -> 0 | Q9: =SUM(Q3:Q8) -> 0 | T9: Total | U9: =U6+U8 -> 6
T11: Afastamentos
T12: Atestados | U12: =L9 -> 3
T13: Faltas | U13: =N9 -> 0
T15: Férias | U15: =Q9 -> 0
T16: Colaboradores | U16: 0
T18: Dias Úteis | U18: 21

Sheet Dezembro
H1: Atestados | M1: Faltas | O1: Férias
B2: Funcionário | C2: Nome do Funcionário | D2: Departamento | E2: Admissão | F2: Demissão | G2: Afastamento | H2: Início | I2: Fim | J2: Início | K2: Fim | L2: Dias | M2: Faltas | N2: Dias | O2: Início | P2: Fim | Q2: Dias | R2: Observação
B3: 7 | C3: AUGUSTO CESAR DA SILVA FILHO | D3: ADM | E3: 45546 | L3: 0 | N3: 0 | Q3: 0 | T3: Início Colab | U3: 5
B4: 5 | C4: GABRIEL FONSECA DA SILVA | D4: ADM | E4: 45477 | F4: 45644 | L4: 0 | M4: 45643 | N4: 1 | Q4: 0 | T4: Admissão | U4: 1
B5: 2 | C5: LEANDRO PINHEIRO DOS SANTO | D5: ADM | E5: 44599 | L5: 0 | N5: 0 | Q5: 0 | T5: Demissão | U5: 1
B6: 6 | C6: LORENA DIAS ALMEIDA | D6: ADM | E6: 45630 | L6: 0 | N6: 0 | Q6: 0 | T6: Fim Colab | U6: =U3+U4-U5 -> 5
B7: 8 | C7: RAFAELA REGINA TAMANHONI | D7: ADM | E7: 45567 | L7: 0 | N7: 0 | Q7: 0
B8: 3 | C8: SAMY HERCULANO PINTO | D8: ADM | E8: 44602 | L8: 0 | N8: 0 | Q8: 0 | T8: Sócio | U8: 2
L9: =SUM(L3:L8) -> 0 | N9: =SUM(N3:N8) -> 1 | Q9: =SUM(Q3:Q8) -> 0 | T9: Total | U9: =U6+U8 -> 7
T11: Afastamentos
T12: Atestados | U12: =L9 -> 0
T13: Faltas | U13: =N9 -> 1
T15: Férias | U15: =Q9 -> 0
T16: Colaboradores | U16: 0
T18: Dias Úteis | U18: 21

Sheet Custo Fopag 25
B2: Telamassas Adm 2025 | C2: Janeiro | D2: Fevereiro | E2: Março | F2: Abril | G2: Maio | H2: Junho | I2: Julho | J2: Agosto | K2: Setembro | L2: Outubro | M2: Novembro | N2: Dezembro | O2: Total | Q2: Período | R2: Faturamento | S2: Custo | T2: % | U2: Meta | V2: Colab | W2: Fat x Colab
B3: Salário | C3: ='Fopag Analitic'!D4 -> 14480 | D3: ='Fopag Analitic'!G4 -> 14300 | E3: ='Fopag Analitic'!J4 -> 12800 | F3: ='Fopag Analitic'!M4 -> 14320 | G3: ='Fopag Analitic'!P14 -> 16000 | H3: ='Fopag Analitic'!S14 -> 11000 | I3: 13733 | J3: 15400 | K3: 12900 | L3: 12900 | M3: 12900 | N3: 9900 | O3: =SUM(C3:N3) -> 160633 | Q3: 45658 | R3: 1738802 | S3: =C12 -> 63760.76 | T3: =S3/R3 -> 0.036669362 | U3: 0.03 | V3: ='Janeiro 25'!U6 -> 6 | W3: =R3/V3 -> 289800.33
B4: Pro Labore | C4: =18000+12500 -> 30500 | D4: =18000+12500 -> 30500 | E4: =18000+12500 -> 30500 | F4: =18000+12500 -> 30500 | G4: =18000+12500 -> 30500 | H4: =18000+12500 -> 30500 | I4: =18000+12500 -> 30500 | J4: =18000+12500 -> 30500 | K4: 30500 | L4: 30500 | M4: ='Fopag 01 26'!B22 -> 32570 | N4: 30500 | O4: =SUM(C4:N4) -> 368070 | Q4: 45689 | R4: 1630074 | S4: =D12 -> 63344.82 | T4: =S4/R4 -> 0.038860089 | U4: 0.03 | V4: ='Fevereiro 25'!U6 -> 6 | W4: =R4/V4 -> 271679
B5: FGTS | C5: ='Fopag Analitic'!D17 -> 1110.4 | D5: ='Fopag Analitic'!G17 -> 1096 | E5: ='Fopag Analitic'!J17 -> 976 | F5: ='Fopag Analitic'!M17 -> 1097.6 | G5: ='Fopag Analitic'!P17 -> 1232 | H5: ='Fopag Analitic'!S17 -> 832 | I5: 1051 | J5: 1232 | K5: 1032 | L5: 1032 | M5: 1032 | N5: 792 | O5: =SUM(C5:N5) -> 12515 | Q5: 45717 | R5: 1537894 | S5: =E12 -> 61036.72 | T5: =S5/R5 -> 0.039688509 | U5: 0.03 | V5: ='Março 25'!U6 -> 6 | W5: =R5/V5 -> 256315.67
B6: INSS+RAT+Terceiros | C6: 3898 | D6: 3740 | E6: ='Fopag Analitic'!J18+'Fopag Analitic'!J19+'Fopag Analitic'!J20 -> 3330.6 | F6: ='Fopag Analitic'!M18+'Fopag Analitic'!M19+'Fopag Analitic'!M20 -> 3745.56 | G6: ='Fopag Analitic'!P18+'Fopag Analitic'!P19+'Fopag Analitic'!P20 -> 4204.2 | H6: ='Fopag Analitic'!S18+'Fopag Analitic'!S19+'Fopag Analitic'!S20 -> 2839.2 | I6: 3585 | J6: 4811 | K6: 4128.9 | L6: 4129 | M6: 4129 | N6: 3310 | O6: =SUM(C6:N6) -> 45850.46 | Q6: 45748 | R6: 1645073 | S6: =F12 -> 63192.37 | T6: =S6/R6 -> 0.03841311 | U6: 0.03 | V6: ='Abril 25'!U5 -> 6 | W6: =R6/V6 -> 274178.83
B7: Provisões | C7: =C3*35.3% -> 5111.44 | D7: =D3*35.3% -> 5047.9 | E7: =E3*35.3% -> 4518.4 | F7: =F3*35.3% -> 5054.96 | G7: =G3*35.3% -> 5648 | H7: =H3*35.3% -> 3883 | I7: =I3*35.3% -> 4847.749 | J7: =J3*35.3% -> 5436.2 | ... M7: =M3*35.3% -> 4553.7 | N7: 2605 | O7: =SUM(C7:N7) -> 55813.749 | Q7: 45778 | R7: 1733520 | S7: =G12 -> 66367.95 | T7: =S7/R7 -> 0.038285079 | U7: 0.03 | V7: ='Maio 25'!U5 -> 6 | W7: =R7/V7 -> 288920
B8: Aj. Custo Diretoria | C8: ='Fopag Analitic'!D28 -> 4000 | D8: ='Fopag Analitic'!G28 -> 4000 | E8: ='Fopag Analitic'!J28 -> 4000 | F8: ='Fopag Analitic'!M28 -> 4000 | G8: ='Fopag Analitic'!P28 -> 4000 | H8: ='Fopag Analitic'!S28 -> 4000 | I8: 4000 | J8: 4000 | K8: 4000 | L8: 4000 | M8: 4000 | N8: 4000 | O8: =SUM(C8:N8) -> 48000 | Q8: 45809 | R8: 1503624 | S8: =H12 -> 57053.2 | T8: =S8/R8 -> 0.037943794 | U8: 0.03 | V8: ='Junho 25'!U5 -> 4 | W8: =R8/V8 -> 375906
B9: Alimentação | C9: ='Fopag Analitic'!D22 -> 3000 | D9: ='Fopag Analitic'!G22 -> 3000 | E9: ='Fopag Analitic'!J22 -> 3150 | F9: ='Fopag Analitic'!M22 -> 2725 | G9: ='Fopag Analitic'!P22 -> 3000 | H9: ='Fopag Analitic'!S22 -> 2000 | I9: 2525 | J9: 3675 | K9: 3080 | L9: 2660 | M9: 3080 | N9: 2520 | O9: =SUM(C9:N9) -> 34415 | Q9: 45839 | R9: 1724204 | S9: =I12 -> 62301.749 | T9: =S9/R9 -> 0.03613363 | U9: 0.03 | V9: ='Julho 25'!U5 -> 5 | W9: =R9/V9 -> 344840.8
B10: Transporte | C10: ='Fopag Analitic'!D23 -> 1134 | D10: ='Fopag Analitic'!G23 -> 1134 | E10: ='Fopag Analitic'!J23 -> 1234.8 | F10: ='Fopag Analitic'!M23 -> 1068.2 | G10: ='Fopag Analitic'!P23 -> 1176 | H10: ='Fopag Analitic'!S23 -> 784 | I10: 990 | J10: 1050 | K10: 880 | L10: 760 | M10: 880 | N10: 630 | O10: =SUM(C10:N10) -> 11721 | Q10: 45870 | R10: 1242847 | S10: =J12 -> 67020.2 | T10: =S10/R10 -> 0.053924739 | U10: 0.03 | V10: 5 | W10: =R10/V10 -> 248569.4
B11: Plano Saúde | C11: ='Fopag Analitic'!D24 -> 526.92 | D11: ='Fopag Analitic'!G24 -> 526.92 | E11: ='Fopag Analitic'!J24 -> 526.92 | F11: ='Fopag Analitic'!M24 -> 681.05 | G11: ='Fopag Analitic'!P24 -> 607.75 | H11: 1215 | I11: 1070 | J11: 916 | K11: 1562.32 | L11: 1369.63 | M11: 1215.5 | N11: 1216 | O11: =SUM(C11:N11) -> 11434.01 | Q11: 45901 | R11: 1940005 | S11: =K12 -> 62636.92 | T11: =S11/R11 -> 0.032286989 | U11: 0.03 | V11: 4 | W11: =R11/V11 -> 485001.25
B12: Total | C12: =SUM(C3:C11) -> 63760.76 | D12: =SUM(D3:D11) -> 63344.82 | E12: =SUM(E3:E11) -> 61036.72 | F12: =SUM(F3:F11) -> 63192.37 | G12: =SUM(G3:G11) -> 66367.95 | H12: =SUM(H3:H11) -> 57053.2 | I12: =SUM(I3:I11) -> 62301.749 | J12: =SUM(J3:J11) -> 67020.2 | ... O12: =SUM(O3:O11) -> 748452.22 | Q12: 45931 | R12: 2011406 | S12: =L12 -> 61904.33 | T12: =S12/R12 -> 0.030776646 | U12: 0.03 | V12: 4 | W12: =R12/V12 -> 502851.5
Q13: 45962 | R13: 1564054 | S13: =M12 -> 64360.2 | T13: =S13/R13 -> 0.041149602 | U13: 0.03 | V13: 4 | W13: =R13/V13 -> 391013.5
B14: Telamassas Adm 2025 | C14: Janeiro | D14: Fevereiro | E14: Março | F14: Abril | G14: Maio | H14: Junho | I14: Julho | J14: Agosto | K14: Setembro | L14: Outubro | M14: Novembro | N14: Dezembro | O14: Total | Q14: 45992 | R14: 1444984 | S14: =N12 -> 55473 | T14: =S14/R14 -> 0.038390044 | U14: 0.03 | V14: 3 | W14: =R14/V14 -> 481661.33
B15: Folha Líquida | C15: 13226 | D15: 13130.21 | E15: 11749.71 | F15: 13076.92 | G15: 14689.69 | H15: 10094.15 | I15: 12554.18 | J15: 14081 | K15: 11783.34 | L15: 9549.1 | M15: =11333.06+4679.17 -> 16012.23 | N15: =9037.22+3829.62 -> 12866.84 | O15: =SUM(C15:N15) -> 152813.37
B16: FGTS | C16: =C5 -> 1110.4 | D16: 1096 | E16: 976 | F16: 1097.6 | G16: 1232 | H16: 832 | I16: 1050.6664 | J16: 1232 | K16: 1032 | L16: 1032 | M16: 1032 | N16: =N5 -> 792 | O16: =SUM(C16:N16) -> 12514.666
B17: INSS Patronal | C17: =C6 -> 3898 | D17: =D6 -> 3740 | E17: 3330.6 | F17: 3745.56 | G17: 4204.2 | H17: 2839.2 | I17: 3585.3991 | J17: 4811.4 | K17: 4129 | L17: 4129 | M17: 4129 | N17: =N6 -> 3310 | O17: =SUM(C17:N17) -> 45851.359
B18: Pro Labore | C18: 30500 | D18: 30500 | E18: 30500 | F18: 30500 | G18: 30500 | H18: 30500 | I18: 30500 | J18: 30500 | K18: 30500 | L18: 30500 | M18: =M4 -> 32570 | N18: 30500 | O18: 0
B19: Aj. Custo Diretoria | C19: 4000 | D19: 4000 | E19: 4000 | F19: 4000 | G19: 4000 | H19: 4000 | I19: 4000 | J19: 4000 | K19: 4000 | L19: 4000 | M19: 4000 | N19: 4000 | O19: =SUM(C19:N19) -> 48000
B20: Alimentação | C20: 3000 | D20: 3000 | E20: 3150 | F20: 2725 | G20: 3000 | H20: 2000 | I20: 2525 | J20: =J9 -> 3675 | K20: 3080 | L20: 2660 | M20: =M9 -> 3080 | N20: =N9 -> 2520 | O20: =SUM(C20:N20) -> 34415
B21: Transporte | C21: 1134 | D21: 1134 | E21: 1234.8 | F21: 1068.2 | G21: 1176 | H21: 784 | I21: 989.8 | J21: =J10 -> 1050 | K21: 880 | L21: 760 | M21: =M10 -> 880 | N21: =N10 -> 630 | O21: =SUM(C21:N21) -> 11720.8
B22: Plano Saúde | C22: 526.92 | D22: 526.92 | E22: 526.92 | F22: 681.05 | G22: 607.75 | H22: 1070.14 | I22: 1070.14 | J22: =J11 -> 916 | K22: 1562 | L22: 1370 | M22: =M11 -> 1215.5 | N22: =N11 -> 1216 | O22: =SUM(C22:N22) -> 11289.34
B23: Total | C23: =SUM(C15:C22) -> 57395.32 | D23: =SUM(D15:D22) -> 57127.13 | E23: =SUM(E15:E22) -> 55468.03 | F23: =SUM(F15:F22) -> 56894.33 | G23: =SUM(G15:G22) -> 59409.64 | H23: =SUM(H15:H22) -> 52119.49 | I23: =SUM(I15:I22) -> 56275.185 | J23: =SUM(J15:J22) -> 60265.4 | ... N23: =SUM(N15:N22) -> 55834.84 | O23: =SUM(O15:O17) -> 211179.4
C24: =C23/R3 -> 0.033008543 | D24: =D23/R4 -> 0.035045728 | E24: =E23/R5 -> 0.036067525 | F24: =F23/R6 -> 0.034584684 | G24: =G23/R7 -> 0.034271102 | H24: =H23/R8 -> 0.034662582 | I24: =I23/R9 -> 0.032638357 | J24: =J23/R10 -> 0.048489798 | K24: =K23/R11 -> 0.029364017 | L24: =L23/R12 -> 0.026846942 | M24: =M23/R13 -> 0.040227978 | N24: =N23/R14 -> 0.038640456

Sheet Dezembro 25
H1: Atestados | M1: Faltas | O1: Férias
B2: Funcionário | C2: Nome do Funcionário | D2: Departamento | E2: Admissão | F2: Demissão | G2: Afastamento | H2: Início | I2: Fim | J2: Início | K2: Fim | L2: Dias | M2: Faltas | N2: Dias | O2: Início | P2: Fim | Q2: Dias | R2: Observação | T2: Início Colab | U2: 4
B3: 2 | C3: LEANDRO PINHEIRO DOS SANTO | D3: ADM | E3: 44599 | L3: 0 | N3: 0 | Q3: 0 | T3: Admissão | U3: 1
B4: 9 | C4: SAMUEL APOLINÁRIO | D4: ADM | E4: 45702 | L4: 0 | N4: 0 | Q4: 0 | T4: Demissão | U4: 2
B5: 11 | C5: SILVANIA BARBOSA ALVES | D5: ADM | E5: 45736 | L5: 0 | N5: 0 | Q5: 0 | T5: Fim Colab | U5: =U2+U3-U4 -> 3
B6: 11 | C6: TATIANI COOK | D6: ADM | E6: 45964 | F6: 46373 | L6: 0 | N6: 0 | Q6: 0
B7: 10 | C7: VIVIANE DA COSTA | D7: ADM | E7: 46364 | F7: 46371 | L7: 0 | N7: 0 | Q7: 0
L8: =SUM(L3:L4) -> 0 | N8: =SUM(N3:N4) -> 0 | Q8: =SUM(Q3:Q4) -> 0 | T8: Sócio | U8: 2
T9: Total | U9: =U5+U8 -> 5
T11: Afastamentos
T12: Atestados | U12: 0
T13: Faltas | U13: =N8 -> 0
T15: Férias | U15: =Q8 -> 0
T16: Colaboradores | U16: 0
T18: Dias Úteis | U18: 22

Sheet Rotatividade 2025
A1: Turnover (Rotatividade de Pessoal) | I1: Absenteísmo (Ausências no Trabalho) | V1: Análise de indicadores | X1: Jan | Y1: Fev | Z1: Mar | AA1: Abr | AB1: Mai | AC1: Jun | AD1: Jul | AE1: Ago | AF1: Set | AG1: Out | AH1: Nov | AI1: Dez
A2: Ano: | D2: 2025 | F2: Meta: | G2: 0.05 | I2: Ano: | L2: 2025 | M2: Meta: | N2: 0.045 | V2: Efetivo Inicial (Un) | X2: 5 | Y2: 6 | Z2: 6 | AA2: 6 | AB2: 6 | AC2: 6 | AD2: 4 | AE2: =AD6 -> 5 | AF2: 5 | AG2: 4 | AH2: 4 | AI2: 4
A3: Mês | B3: Admissões | C3: Desligamentos | D3: Colaboradores | E3: Turnover | F3: Média | G3: Meta | I3: Mês | J3: H Program | K3: H. N. Prod. | L3: Absenteísmo | M3: Média | N3: Meta | V3: Afastamentos + Faltas (dias) | X3: 3 | Y3: 0 | Z3: 1 | AA3: 0 | AB3: 5 | AC3: 0 | AD3: 0 | AE3: 0 | AF3: 0 | AG3: 0 | AH3: 0 | AI3: 0
A4: Jan | B4: 1 | C4: 0 | D4: 5 | E4: =IF($D4=0,0,((C4+B4)/2/D4)) -> 0.1 | F4: =AVERAGE(E4) -> 0.1 | G4: =$G$2 -> 0.05 | I4: Jan | J4: 1161.6 | K4: 26.4 | L4: =IFERROR((K4/J4),"") -> 0.022727273 | M4: =AVERAGE(L4) -> 0.022727273 | N4: =$N$2 -> 0.045 | V4: Novas Contratações (Un) | X4: 1 | Y4: 2 | Z4: 2 | AA4: 1 | AB4: 0 | AC4: 0 | AD4: 1 | AE4: 0 | AF4: 0 | AG4: 0 | AH4: 1 | AI4: 1
A5: Fev | B5: 2 | C5: 2 | D5: 6 | E5: =IF($D5=0,0,((C5+B5)/2/D5)) -> 0.33333333 | F5: =AVERAGE($E$4:$E5) -> 0.21666667 | G5: =$G$2 -> 0.05 | I5: Fev | J5: 1056 | K5: 0 | L5: =IFERROR((K5/J5),"") -> 0 | M5: =AVERAGE($L$4:$L5) -> 0.011363636 | N5: =$N$2 -> 0.045 | V5: Desligamentos (Un) | X5: 0 | Y5: 2 | Z5: 2 | AA5: 1 | AB5: 0 | AC5: 2 | AD5: 0 | AE5: 0 | AF5: 1 | AG5: 0 | AH5: 1 | AI5: 2
A6: Mar | B6: 2 | C6: 2 | D6: 6 | E6: =IF($D6=0,0,((C6+B6)/2/D6)) -> 0.33333333 | F6: =AVERAGE($E$4:$E6) -> 0.25555556 | G6: =$G$2 -> 0.05 | I6: Mar | J6: 1108.8 | K6: 8.8 | L6: =IFERROR((K6/J6),"") -> 0.0079365079 | M6: =AVERAGE($L$4:$L6) -> 0.01022126 | N6: =$N$2 -> 0.045 | V6: Efetivo Final (Un) | X6: =X2+X4-X5 -> 6 | Y6: =Y2+Y4-Y5 -> 6 | Z6: =Z2+Z4-Z5 -> 6 | AA6: =AA2+AA4-AA5 -> 6 | AB6: =AB2+AB4-AB5 -> 6 | AC6: =AC2+AC4-AC5 -> 4 | AD6: =AD2+AD4-AD5 -> 5 | AE6: =AE2+AE4-AE5 -> 5 | ... AI6: =AI2+AI4-AI5 -> 3
A7: Abr | B7: 1 | C7: 1 | D7: 6 | E7: =IF($D7=0,0,((C7+B7)/2/D7)) -> 0.16666667 | F7: =AVERAGE($E$4:$E7) -> 0.23333333 | G7: =$G$2 -> 0.05 | I7: Abr | J7: 1267.2 | K7: 0 | L7: =IFERROR((K7/J7),"") -> 0 | M7: =AVERAGE($L$4:$L7) -> 0.0076659452 | N7: =$N$2 -> 0.045 | V7: Efetivo Médio | X7: =(X2+X6)/2 -> 5.5 | Y7: =(Y2+Y6)/2 -> 6 | Z7: =(Z2+Z6)/2 -> 6 | AA7: =(AA2+AA6)/2 -> 6 | AB7: =(AB2+AB6)/2 -> 6 | AC7: =(AC2+AC6)/2 -> 5 | AD7: =(AD2+AD6)/2 -> 4.5 | AE7: =(AE2+AE6)/2 -> 5 | ... AI7: =(AI2+AI6)/2 -> 3.5
A8: Mai | B8: 0 | C8: 0 | D8: 6 | E8: =IF($D8=0,0,((C8+B8)/2/D8)) -> 0 | F8: =AVERAGE($E$4:$E8) -> 0.18666667 | G8: =$G$2 -> 0.05 | I8: Mai | J8: 1161.6 | K8: 44 | L8: =IFERROR((K8/J8),"") -> 0.037878788 | M8: =AVERAGE($L$4:$L8) -> 0.013708514 | N8: =$N$2 -> 0.045 | V8: Férias (dias não produtivos) | X8: ='Janeiro 25'!AP15 -> 0 | Y8: 0 | Z8: 0 | AA8: 0 | AB8: 0 | AC8: 0 | AD8: 0 | AE8: 0 | AF8: 0 | AG8: 13 | AH8: 0 | AI8: 0
A9: Jun | B9: 0 | C9: 2 | D9: 4 | E9: =IF($D9=0,0,((C9+B9)/2/D9)) -> 0.25 | F9: =AVERAGE($E$4:$E9) -> 0.19722222 | G9: =$G$2 -> 0.05 | I9: Jun | J9: 704 | K9: 0 | L9: =IFERROR((K9/J9),"") -> 0 | M9: =AVERAGE($L$4:$L9) -> 0.011423761 | N9: =$N$2 -> 0.045 | V9: Colaboradores de Férias (Un) | X9: ='Janeiro 25'!AP16 -> 0 | Y9: 0 | Z9: 0 | AA9: 0 | AB9: 0 | AC9: 0 | AD9: 0 | AE9: 0 | AF9: 0 | AG9: 1 | AH9: 0 | AI9: 0
A10: Jul | B10: 1 | C10: 0 | D10: 5 | E10: =IF($D10=0,0,((C10+B10)/2/D10)) -> 0.1 | F10: =AVERAGE($E$4:$E10) -> 0.18333333 | G10: =$G$2 -> 0.05 | I10: Jul | J10: 1012 | K10: 0 | L10: =IFERROR((K10/J10),"") -> 0 | M10: =AVERAGE($L$4:$L10) -> 0.0097917955 | N10: =$N$2 -> 0.045 | V10: Dias Úteis | X10: 22 | Y10: 20 | Z10: 21 | AA10: 24 | AB10: 22 | AC10: 20 | AD10: 23 | AE10: 21 | AF10: 22 | AG10: 23 | AH10: 21 | AI10: 22
A11: Ago | B11: 0 | C11: 0 | D11: 5 | E11: =IF($D11=0,0,((C11+B11)/2/D11)) -> 0 | F11: =AVERAGE($E$4:$E11) -> 0.16041667 | G11: =$G$2 -> 0.05 | I11: Ago | J11: 924 | K11: 0 | L11: =IFERROR((K11/J11),"") -> 0 | M11: =AVERAGE($L$4:$L11) -> 0.0085678211 | N11: =$N$2 -> 0.045 | V11: Dias Programados | X11: =X10*X7 -> 121 | Y11: =Y10*Y7 -> 120 | Z11: =Z10*Z7 -> 126 | AA11: =AA10*AA7 -> 144 | AB11: =AB10*AB7 -> 132 | AC11: =AC10*AC7 -> 100 | AD11: =AD10*AD7 -> 103.5 | AE11: =AE10*AE7 -> 105 | ... AI11: =AI10*AI7 -> 77
A12: Set | B12: 0 | C12: 1 | D12: 4 | E12: =IF($D12=0,0,((C12+B12)/2/D12)) -> 0.125 | F12: =AVERAGE($E$4:$E12) -> 0.15648148 | G12: =$G$2 -> 0.05 | I12: Set | J12: 774 | K12: 0 | L12: =IFERROR((K12/J12),"") -> 0 | M12: =AVERAGE($L$4:$L12) -> 0.0076158409 | N12: =$N$2 -> 0.045 | V12: Dias Produtivos | X12: =X11-X8 -> 121 | Y12: =Y11-Y8 -> 120 | Z12: =Z11-Z8 -> 126 | AA12: =AA11-AA8 -> 144 | AB12: =AB11-AB8 -> 132 | AC12: =AC11-AC8 -> 100 | AD12: =AD11-AD8 -> 103.5 | AE12: =AE11-AE8 -> 105 | ... AI12: =AI11-AI8 -> 77
A13: Out | B13: 0 | C13: 0 | D13: 4 | E13: =IF($D13=0,0,((C13+B13)/2/D13)) -> 0 | F13: =AVERAGE($E$4:$E13) -> 0.14083333 | G13: =$G$2 -> 0.05 | I13: Out | J13: 810 | K13: 114 | L13: =IFERROR((K13/J13),"") -> 0.14074074 | M13: =AVERAGE($L$4:$L13) -> 0.020928331 | N13: =$N$2 -> 0.045 | V13: Dias não Produtivos | X13: =X8+X3 -> 3 | Y13: =Y8+Y3 -> 0 | Z13: =Z8+Z3 -> 1 | AA13: =AA8+AA3 -> 0 | AB13: =AB8+AB3 -> 5 | AC13: =AC8+AC3 -> 0 | AD13: =AD8+AD3 -> 0 | AE13: =AE8+AE3 -> 0 | ... AI13: =AI8+AI3 -> 0
A14: Nov | B14: 1 | C14: 1 | D14: 4 | E14: =IF($D14=0,0,((C14+B14)/2/D14)) -> 0.25 | F14: =AVERAGE($E$4:$E14) -> 0.15075758 | G14: =$G$2 -> 0.05 | I14: Nov | J14: 739 | K14: 0 | L14: =IFERROR((K14/J14),"") -> 0 | M14: =AVERAGE($L$4:$L14) -> 0.019025755 | N14: =$N$2 -> 0.045 | V14: Horas Programadas | X14: =(X6*8.8)*X10 -> 1161.6 | Y14: =(Y6*8.8)*Y10 -> 1056 | Z14: =(Z6*8.8)*Z10 -> 1108.8 | AA14: =(AA6*8.8)*AA10 -> 1267.2 | AB14: =(AB6*8.8)*AB10 -> 1161.6 | AC14: =(AC6*8.8)*AC10 -> 704 | AD14: =(AD6*8.8)*AD10 -> 1012 | AE14: =(AE6*8.8)*AE10 -> 924 | ... AI14: =(AI6*8.8)*AI10 -> 580.8
A15: Dez | B15: 1 | C15: 2 | D15: 3 | E15: =IF($D15=0,0,((C15+B15)/2/D15)) -> 0.5 | F15: =AVERAGE($E$4:$E15) -> 0.17986111 | G15: =$G$2 -> 0.05 | I15: Dez | J15: =AI14 -> 580.8 | K15: =AI15 -> 0 | L15: =IFERROR((K15/J15),"") -> 0 | M15: =AVERAGE($L$4:$L15) -> 0.017440276 | N15: =$N$2 -> 0.045 | V15: Horas não Produtivas | X15: =X13*8.8 -> 26.4 | Y15: =Y13*8.8 -> 0 | Z15: =Z13*8.8 -> 8.8 | AA15: =AA13*8.8 -> 0 | AB15: =AB13*8.8 -> 44 | AC15: =AC13*8.8 -> 0 | AD15: =AD13*8.8 -> 0 | AE15: =AE13*8.8 -> 0 | ... AI15: =AI13*8.8 -> 0
A16: Cálculo: [(Nº de desligados + Nº de admitidos) / 2] / (Nº total de colaboradores). | V16: Efetivo Pessoal Mês | X16: =(X14-X15)/(8.8*X10) -> 5.8636364 | Y16: =(Y14-Y15)/(8.8*Y10) -> 6 | Z16: =(Z14-Z15)/(8.8*Z10) -> 5.952381 | AA16: =(AA14-AA15)/(8.8*AA10) -> 6 | AB16: =(AB14-AB15)/(8.8*AB10) -> 5.7727273 | AC16: =(AC14-AC15)/(8.8*AC10) -> 4 | AD16: =(AD14-AD15)/(8.8*AD10) -> 5 | AE16: =(AE14-AE15)/(8.8*AE10) -> 5 | ... AI16: =(AI14-AI15)/(8.8*AI10) -> 3
V17: Taxa de Absenteísmo | X17: =IFERROR((X15/X14),"") -> 0.022727273 | Y17: =IFERROR((Y15/Y14),"") -> 0 | Z17: =IFERROR((Z15/Z14),"") -> 0.0079365079 | AA17: =IFERROR((AA15/AA14),"") -> 0 | AB17: =IFERROR((AB15/AB14),"") -> 0.037878788 | AC17: =IFERROR((AC15/AC14),"") -> 0 | AD17: =IFERROR((AD15/AD14),"") -> 0 | AE17: =IFERROR((AE15/AE14),"") -> 0 | ... AI17: =IFERROR((AI15/AI14),"") -> 0

Sheet ADM_Cadastro
B2: Funcionário | C2: Nome do Funcionário | D2: Departamento | E2: Admissão | F2: Demissão
B3: 1 | C3: LEANDRO PINHEIRO DOS SANTO | D3: ADM | E3: 44599
B4: 2 | C4: SAMUEL APOLINÁRIO | D4: ADM | E4: 45702
B5: 3 | C5: SILVANIA BARBOSA ALVES | D5: ADM | E5: 45736
B6: 4 | C6: MANOELA SILVA | D6: ADM | E6: 46043
B7: 5 | C7: FELIPE ROCHA | D7: ADM | E7: 46055 | F7: 46129
B8: 6 | C8: HENRIQUE CAZEDEI | D8: ADM | E8: 46055

Sheet Rotatividade 2026
A1: Turnover (Rotatividade de Pessoal) | I1: Absenteísmo (Ausências no Trabalho) | Q1: Análise de indicadores | R1: Jan | S1: Fev | T1: Mar | U1: Abr | V1: Mai | W1: Jun | X1: Jul | Y1: Ago | Z1: Set | AA1: Out | AB1: Nov | AC1: Dez
A2: Ano: | D2: 2026 | F2: Meta: | G2: 0.05 | I2: Ano: | L2: 2026 | M2: Meta: | N2: 0.045 | Q2: Efetivo Inicial (Un) | R2: 3 | S2: =R6 -> 4 | T2: =S6 -> 6 | U2: =T6 -> 6 | V2: =U6 -> 5 | W2: =V6 -> 5 | X2: =W6 -> 5 | Y2: =X6 -> 5 | Z2: =Y6 -> 5 | ... AC2: =AB6 -> 5
A3: Mês | B3: Admissões | C3: Desligamentos | D3: Colaboradores | E3: Turnover | F3: Média | G3: Meta | I3: Mês | J3: H Program | K3: H. N. Prod. | L3: Absenteísmo | M3: Média | N3: Meta | Q3: Afastamentos + Faltas (dias) | R3: 0 | S3: 0 | T3: 0 | U3: 10
A4: Jan | B4: 1 | C4: 0 | D4: 4 | E4: =Table_46[[#This Row],[Desligamentos]]/Table_46[[#This Row],[Colaboradores]] -> 0 | F4: =AVERAGE(E4) -> 0 | G4: =$G$2 -> 0.05 | I4: Jan | J4: =R14 -> 739.2 | K4: =R15 -> 0 | L4: =IFERROR((K4/J4),"") -> 0 | M4: =AVERAGE(L4) -> 0 | N4: =$N$2 -> 0.045 | Q4: Novas Contratações (Un) | R4: 1 | S4: 2 | T4: 0 | U4: 0
A5: Fev | B5: 2 | C5: 0 | D5: 6 | E5: =Table_46[[#This Row],[Desligamentos]]/Table_46[[#This Row],[Colaboradores]] -> 0 | F5: =AVERAGE($E$4:$E5) -> 0 | G5: =$G$2 -> 0.05 | I5: Fev | J5: =S14 -> 1003.2 | K5: =S15 -> 0 | L5: =IFERROR((K5/J5),"") -> 0 | M5: =AVERAGE($L$4:$L5) -> 0 | N5: =$N$2 -> 0.045 | Q5: Desligamentos (Un) | R5: 0 | S5: 0 | T5: 0 | U5: 1
A6: Mar | B6: 0 | C6: 0 | D6: 6 | E6: =Table_46[[#This Row],[Desligamentos]]/Table_46[[#This Row],[Colaboradores]] -> 0 | F6: =AVERAGE($E$4:$E6) -> 0 | G6: =$G$2 -> 0.05 | I6: Mar | J6: =T14 -> 1161.6 | K6: =T15 -> 0 | L6: =IFERROR((K6/J6),"") -> 0 | M6: =AVERAGE($L$4:$L6) -> 0 | N6: =$N$2 -> 0.045 | Q6: Efetivo Final (Un) | R6: =R2+R4-R5 -> 4 | S6: =S2+S4-S5 -> 6 | T6: =T2+T4-T5 -> 6 | U6: =U2+U4-U5 -> 5 | V6: =V2+V4-V5 -> 5 | W6: =W2+W4-W5 -> 5 | X6: =X2+X4-X5 -> 5 | Y6: =Y2+Y4-Y5 -> 5 | ... AC6: =AC2+AC4-AC5 -> 5
A7: Abr | B7: 0 | C7: 1 | D7: 5 | E7: =Table_46[[#This Row],[Desligamentos]]/Table_46[[#This Row],[Colaboradores]] -> 0.2 | F7: =AVERAGE($E$4:$E7) -> 0.05 | G7: =$G$2 -> 0.05 | I7: Abr | J7: =U14 -> 880 | K7: =U15 -> 88 | L7: =IFERROR((K7/J7),"") -> 0.1 | M7: =AVERAGE($L$4:$L7) -> 0.025 | N7: =$N$2 -> 0.045 | Q7: Efetivo Médio | R7: =(R2+R6)/2 -> 3.5 | S7: =(S2+S6)/2 -> 5 | T7: =(T2+T6)/2 -> 6 | U7: =(U2+U6)/2 -> 5.5 | V7: =(V2+V6)/2 -> 5 | W7: =(W2+W6)/2 -> 5 | X7: =(X2+X6)/2 -> 5 | Y7: =(Y2+Y6)/2 -> 5 | ... AC7: =(AC2+AC6)/2 -> 5
A8: Mai | E8: =Table_46[[#This Row],[Desligamentos]]/Table_46[[#This Row],[Colaboradores]] -> #DIV/0! | F8: =AVERAGE($E$4:$E8) -> #DIV/0! | G8: =$G$2 -> 0.05 | I8: Mai | M8: =AVERAGE($L$4:$L8) -> 0.025 | N8: =$N$2 -> 0.045 | Q8: Férias (dias não produtivos) | R8: 0 | S8: 0 | T8: 0 | U8: 0
A9: Jun | E9: =Table_46[[#This Row],[Desligamentos]]/Table_46[[#This Row],[Colaboradores]] -> #DIV/0! | F9: =AVERAGE($E$4:$E9) -> #DIV/0! | G9: =$G$2 -> 0.05 | I9: Jun | M9: =AVERAGE($L$4:$L9) -> 0.025 | N9: =$N$2 -> 0.045 | Q9: Colaboradores de Férias (Un) | R9: 0 | S9: 0 | T9: 0 | U9: 0
A10: Jul | E10: =Table_46[[#This Row],[Desligamentos]]/Table_46[[#This Row],[Colaboradores]] -> #DIV/0! | F10: =AVERAGE($E$4:$E10) -> #DIV/0! | G10: =$G$2 -> 0.05 | I10: Jul | M10: =AVERAGE($L$4:$L10) -> 0.025 | N10: =$N$2 -> 0.045 | Q10: Dias Úteis | R10: 21 | S10: 19 | T10: 22 | U10: 20
A11: Ago | E11: =Table_46[[#This Row],[Desligamentos]]/Table_46[[#This Row],[Colaboradores]] -> #DIV/0! | F11: =AVERAGE($E$4:$E11) -> #DIV/0! | G11: =$G$2 -> 0.05 | I11: Ago | M11: =AVERAGE($L$4:$L11) -> 0.025 | N11: =$N$2 -> 0.045 | Q11: Dias Programados | R11: =R10*R7 -> 73.5 | S11: =S10*S7 -> 95 | T11: =T10*T7 -> 132 | U11: =U10*U7 -> 110
A12: Set | E12: =Table_46[[#This Row],[Desligamentos]]/Table_46[[#This Row],[Colaboradores]] -> #DIV/0! | F12: =AVERAGE($E$4:$E12) -> #DIV/0! | G12: =$G$2 -> 0.05 | I12: Set | M12: =AVERAGE($L$4:$L12) -> 0.025 | N12: =$N$2 -> 0.045 | Q12: Dias Produtivos | R12: =R11-R8 -> 73.5 | S12: =S11-S8 -> 95 | T12: =T11-T8 -> 132 | U12: =U11-U8 -> 110
A13: Out | E13: =Table_46[[#This Row],[Desligamentos]]/Table_46[[#This Row],[Colaboradores]] -> #DIV/0! | F13: =AVERAGE($E$4:$E13) -> #DIV/0! | G13: =$G$2 -> 0.05 | I13: Out | M13: =AVERAGE($L$4:$L13) -> 0.025 | N13: =$N$2 -> 0.045 | Q13: Dias não Produtivos | R13: =R8+R3 -> 0 | S13: =S8+S3 -> 0 | T13: =T8+T3 -> 0 | U13: =U8+U3 -> 10
A14: Nov | E14: =Table_46[[#This Row],[Desligamentos]]/Table_46[[#This Row],[Colaboradores]] -> #DIV/0! | F14: =AVERAGE($E$4:$E14) -> #DIV/0! | G14: =$G$2 -> 0.05 | I14: Nov | M14: =AVERAGE($L$4:$L14) -> 0.025 | N14: =$N$2 -> 0.045 | Q14: Horas Programadas | R14: =(R6*8.8)*R10 -> 739.2 | S14: =(S6*8.8)*S10 -> 1003.2 | T14: =(T6*8.8)*T10 -> 1161.6 | U14: =(U6*8.8)*U10 -> 880
A15: Dez | E15: =Table_46[[#This Row],[Desligamentos]]/Table_46[[#This Row],[Colaboradores]] -> #DIV/0! | F15: =AVERAGE($E$4:$E15) -> #DIV/0! | G15: =$G$2 -> 0.05 | I15: Dez | M15: =AVERAGE($L$4:$L15) -> 0.025 | N15: =$N$2 -> 0.045 | Q15: Horas não Produtivas | R15: =R13*8.8 -> 0 | S15: =S13*8.8 -> 0 | T15: =T13*8.8 -> 0 | U15: =U13*8.8 -> 88
A16: Cálculo: [(Nº de desligados + Nº de admitidos) / 2] / (Nº total de colaboradores). | Q16: Efetivo Pessoal Mês | R16: =(R14-R15)/(8.8*R10) -> 4 | S16: =(S14-S15)/(8.8*S10) -> 6 | T16: =(T14-T15)/(8.8*T10) -> 6 | U16: =(U14-U15)/(8.8*U10) -> 4.5

Sheet Janeiro 25
H1: Atestados | M1: Faltas | O1: Férias
B2: Funcionário | C2: Nome do Funcionário | D2: Departamento | E2: Admissão | F2: Demissão | G2: Afastamento | H2: Início | I2: Fim | J2: Início | K2: Fim | L2: Dias | M2: Faltas | N2: Dias | O2: Início | P2: Fim | Q2: Dias | R2: Observação
B3: 7 | C3: AUGUSTO CESAR DA SILVA FILHO | D3: ADM | E3: 45546 | L3: 0 | N3: 0 | Q3: 0 | T3: Início Colab | U3: 5
B4: 5 | C4: JOSE OLIVEIRA JUNIOR | D4: ADM | E4: 45667 | L4: 0 | N4: 0 | Q4: 0 | T4: Admissão | U4: 1
B5: 2 | C5: LEANDRO PINHEIRO DOS SANTO | D5: ADM | E5: 44599 | L5: 0 | N5: 0 | Q5: 0 | T5: Demissão | U5: 0
B6: 6 | C6: LORENA DIAS ALMEIDA | D6: ADM | E6: 45630 | L6: 0 | N6: 0 | Q6: 0 | T6: Fim Colab | U6: =U3+U4-U5 -> 6
B7: 8 | C7: RAFAELA REGINA TAMANHONI | D7: ADM | E7: 45567 | H7: 45686 | I7: 45688 | L7: 3 | N7: 0 | Q7: 0
B8: 3 | C8: SAMY HERCULANO PINTO | D8: ADM | E8: 44602 | L8: 0 | N8: 0 | Q8: 0 | T8: Sócio | U8: 2
L9: =SUM(L3:L8) -> 3 | N9: =SUM(N3:N8) -> 0 | Q9: =SUM(Q3:Q8) -> 0 | T9: Total | U9: =U6+U8 -> 8
T11: Afastamentos
T12: Atestados | U12: =L9 -> 3
T13: Faltas | U13: =N9 -> 0
T15: Férias | U15: =Q9 -> 0
T16: Colaboradores | U16: 0
T18: Dias Úteis | U18: 22

Sheet Fevereiro 25
H1: Atestados | M1: Faltas | O1: Férias
B2: Funcionário | C2: Nome do Funcionário | D2: Departamento | E2: Admissão | F2: Demissão | G2: Afastamento | H2: Início | I2: Fim | J2: Início | K2: Fim | L2: Dias | M2: Faltas | N2: Dias | O2: Início | P2: Fim | Q2: Dias | R2: Observação
B3: 4 | C3: AUGUSTO CESAR DA SILVA FILHO | D3: ADM | E3: 45546 | L3: 0 | N3: 0 | Q3: 0 | T3: Início Colab | U3: 6
B4: 5 | C4: JOSE OLIVEIRA JUNIOR | D4: ADM | E4: 45667 | F4: 45695 | L4: 0 | N4: 0 | Q4: 0 | T4: Admissão | U4: 2
B5: 2 | C5: LEANDRO PINHEIRO DOS SANTO | D5: ADM | E5: 44599 | L5: 0 | N5: 0 | Q5: 0 | T5: Demissão | U5: 2
B6: 6 | C6: LORENA DIAS ALMEIDA | D6: ADM | E6: 45630 | L6: 0 | N6: 0 | Q6: 0 | T6: Fim Colab | U6: =U3+U4-U5 -> 6
B7: 7 | C7: MARLY DA SILVA VALANDRO | D7: ADM | E7: 45693 | L7: 0 | N7: 0 | Q7: 0
B8: 8 | C8: RAFAELA REGINA TAMANHONI | D8: ADM | E8: 45567 | F8: 45691 | L8: 0 | N8: 0 | Q8: 0 | T8: Sócio | U8: 2
B9: 9 | C9: SAMUEL APOLINÁRIO | D9: ADM | E9: 45702 | L9: 0 | N9: 0 | Q9: 0 | T9: Total | U9: =U6+U8 -> 8
B10: 3 | C10: SAMY HERCULANO PINTO | D10: ADM | E10: 44602 | L10: 0 | N10: 0 | Q10: 0
L11: =SUM(L3:L10) -> 0 | N11: =SUM(N3:N10) -> 0 | Q11: =SUM(Q3:Q10) -> 0 | T11: Afastamentos
T12: Atestados | U12: =L11 -> 0
T13: Faltas | U13: =N11 -> 0
T15: Férias | U15: =Q11 -> 0
T16: Colaboradores | U16: 0
T18: Dias Úteis | U18: 20

Sheet Março 25
H1: Atestados | M1: Faltas | O1: Férias
B2: Funcionário | C2: Nome do Funcionário | D2: Departamento | E2: Admissão | F2: Demissão | G2: Afastamento | H2: Início | I2: Fim | J2: Início | K2: Fim | L2: Dias | M2: Faltas | N2: Dias | O2: Início | P2: Fim | Q2: Dias | R2: Observação
B3: 4 | C3: AUGUSTO CESAR DA SILVA FILHO | D3: ADM | E3: 45546 | F3: 45742 | L3: 0 | N3: 0 | Q3: 0 | T3: Início Colab | U3: 6
B4: 2 | C4: LEANDRO PINHEIRO DOS SANTO | D4: ADM | E4: 44599 | L4: 0 | N4: 0 | Q4: 0 | T4: Admissão | U4: 2
B5: 6 | C5: LORENA DIAS ALMEIDA | D5: ADM | E5: 45630 | F5: 45719 | L5: 0 | N5: 0 | Q5: 0 | R5: pedido de demissão | T5: Demissão | U5: 2
B6: 7 | C6: MARLY DA SILVA VALANDRO | D6: ADM | E6: 45693 | L6: 0 | N6: 0 | Q6: 0 | T6: Fim Colab | U6: =U3+U4-U5 -> 6
B7: 9 | C7: SAMUEL APOLINÁRIO | D7: ADM | E7: 45702 | L7: 0 | N7: 0 | Q7: 0
B8: 3 | C8: SAMY HERCULANO PINTO | D8: ADM | E8: 44602 | H8: 45741 | I8: 45741 | L8: 1 | N8: 0 | Q8: 0 | T8: Sócio | U8: 2
B9: 11 | C9: SILVANIA BARBOSA ALVES | D9: ADM | E9: 45736 | L9: 0 | N9: 0 | Q9: 0 | T9: Total | U9: =U6+U8 -> 8
B10: 10 | C10: VINICIUS ABRAO SACRAMENTO | D10: ADM | E10: 45734 | L10: 0 | N10: 0 | Q10: 0
L11: =SUM(L3:L8) -> 1 | N11: =SUM(N3:N8) -> 0 | Q11: =SUM(Q3:Q8) -> 0 | T11: Afastamentos
T12: Atestados | U12: =L11 -> 1
T13: Faltas | U13: =N11 -> 0
T15: Férias | U15: =Q11 -> 0
T16: Colaboradores | U16: 0
T18: Dias Úteis | U18: 21

Sheet Abril 25
H1: Atestados | M1: Faltas | O1: Férias
B2: Funcionário | C2: Nome do Funcionário | D2: Departamento | E2: Admissão | F2: Demissão | G2: Afastamento | H2: Início | I2: Fim | J2: Início | K2: Fim | L2: Dias | M2: Faltas | N2: Dias | O2: Início | P2: Fim | Q2: Dias | R2: Observação | T2: Início Colab | U2: ='Março 25'!U6 -> 6
B3: 2 | C3: LEANDRO PINHEIRO DOS SANTO | D3: ADM | E3: 44599 | L3: 0 | N3: 0 | Q3: 0 | T3: Admissão | U3: 1
B4: 11 | C4: DIOGO GAVA | D4: ADM | E4: 45770 | L4: 0 | N4: 0 | Q4: 0 | T4: Demissão | U4: 1
B5: 7 | C5: MARLY DA SILVA VALANDRO | D5: ADM | E5: 45693 | L5: 0 | N5: 0 | Q5: 0 | T5: Fim Colab | U5: =U2+U3-U4 -> 6
B6: 8 | C6: SAMUEL APOLINÁRIO | D6: ADM | E6: 45702 | L6: 0 | N6: 0 | Q6: 0
B7: 3 | C7: SAMY HERCULANO PINTO | D7: ADM | E7: 44602 | F7: 45760 | L7: 0 | N7: 0 | Q7: 0 | T7: Sócio | U7: 2
B8: 10 | C8: SILVANIA BARBOSA ALVES | D8: ADM | E8: 45736 | L8: 0 | N8: 0 | Q8: 0 | T8: Total | U8: =U5+U7 -> 8
B9: 9 | C9: VINICIUS ABRAO SACRAMENTO | D9: ADM | E9: 45734 | L9: 0 | N9: 0 | Q9: 0
L10: =SUM(L3:L7) -> 0 | N10: =SUM(N3:N7) -> 0 | Q10: =SUM(Q3:Q7) -> 0 | T10: Afastamentos
T11: Atestados | U11: =L10 -> 0
T12: Faltas | U12: =N10 -> 0
T14: Férias | U14: =Q10 -> 0
T15: Colaboradores | U15: 0
T17: Dias Úteis | U17: =#REF! -> #REF!

Sheet Maio 25
H1: Atestados | M1: Faltas | O1: Férias
B2: Funcionário | C2: Nome do Funcionário | D2: Departamento | E2: Admissão | F2: Demissão | G2: Afastamento | H2: Início | I2: Fim | J2: Início | K2: Fim | L2: Dias | M2: Faltas | N2: Dias | O2: Início | P2: Fim | Q2: Dias | R2: Observação | T2: Início Colab | U2: ='Abril 25'!U5 -> 6
B3: 2 | C3: LEANDRO PINHEIRO DOS SANTO | D3: ADM | E3: 44599 | L3: 0 | N3: 0 | Q3: 0 | T3: Admissão | U3: 0
B4: 11 | C4: DIOGO GAVA | D4: ADM | E4: 45770 | H4: 45804 | I4: 45805 | L4: 2 | N4: 0 | Q4: 0 | T4: Demissão | U4: 0
B5: 7 | C5: MARLY DA SILVA VALANDRO | D5: ADM | E5: 45693 | H5: 45782 | I5: 45784 | L5: 3 | N5: 0 | Q5: 0 | T5: Fim Colab | U5: =U2+U3-U4 -> 6
B6: 8 | C6: SAMUEL APOLINÁRIO | D6: ADM | E6: 45702 | L6: 0 | N6: 0 | Q6: 0
B7: 10 | C7: SILVANIA BARBOSA ALVES | D7: ADM | E7: 45736 | L7: 0 | N7: 0 | Q7: 0 | T7: Sócio | U7: 2
B8: 9 | C8: VINICIUS ABRAO SACRAMENTO | D8: ADM | E8: 45734 | L8: 0 | N8: 0 | Q8: 0 | T8: Total | U8: =U5+U7 -> 8
L9: =SUM(L3:L6) -> 5 | N9: =SUM(N3:N6) -> 0 | Q9: =SUM(Q3:Q6) -> 0
T10: Afastamentos
T11: Atestados | U11: 5
T12: Faltas | U12: =N9 -> 0
T14: Férias | U14: =Q9 -> 0
T15: Colaboradores | U15: 0
T17: Dias Úteis | U17: 20

Sheet Junho 25
H1: Atestados | M1: Faltas | O1: Férias
B2: Funcionário | C2: Nome do Funcionário | D2: Departamento | E2: Admissão | F2: Demissão | G2: Afastamento | H2: Início | I2: Fim | J2: Início | K2: Fim | L2: Dias | M2: Faltas | N2: Dias | O2: Início | P2: Fim | Q2: Dias | R2: Observação | T2: Início Colab | U2: ='Maio 25'!U5 -> 6
B3: 2 | C3: LEANDRO PINHEIRO DOS SANTO | D3: ADM | E3: 44599 | L3: 0 | N3: 0 | Q3: 0 | T3: Admissão | U3: 0
B4: 11 | C4: DIOGO GAVA | D4: ADM | E4: 45770 | F4: 45814 | L4: 0 | N4: 0 | Q4: 0 | T4: Demissão | U4: 2
B5: 7 | C5: MARLY DA SILVA VALANDRO | D5: ADM | E5: 45693 | F5: 45819 | L5: 0 | N5: 0 | Q5: 0 | T5: Fim Colab | U5: =U2+U3-U4 -> 4
B6: 9 | C6: SAMUEL APOLINÁRIO | D6: ADM | E6: 45702 | L6: 0 | N6: 0 | Q6: 0
B7: 11 | C7: SILVANIA BARBOSA ALVES | D7: ADM | E7: 45736 | L7: 0 | N7: 0 | Q7: 0 | T7: Sócio | U7: 2
B8: 10 | C8: VINICIUS ABRAO SACRAMENTO | D8: ADM | E8: 45734 | L8: 0 | N8: 0 | Q8: 0 | T8: Total | U8: =U5+U7 -> 6
L9: =SUM(L3:L6) -> 0 | N9: =SUM(N3:N6) -> 0 | Q9: =SUM(Q3:Q6) -> 0
T10: Afastamentos
T11: Atestados | U11: 0
T12: Faltas | U12: =N9 -> 0
T14: Férias | U14: =Q9 -> 0
T15: Colaboradores | U15: 0
T17: Dias Úteis | U17: 20

Sheet Julho 25
H1: Atestados | M1: Faltas | O1: Férias
B2: Funcionário | C2: Nome do Funcionário | D2: Departamento | E2: Admissão | F2: Demissão | G2: Afastamento | H2: Início | I2: Fim | J2: Início | K2: Fim | L2: Dias | M2: Faltas | N2: Dias | O2: Início | P2: Fim | Q2: Dias | R2: Observação | T2: Início Colab | U2: 4
B3: 12 | C3: FERNANDO DA SILVA SALARINI | D3: ADM | E3: 45861 | L3: 0 | N3: 0 | Q3: 0 | T3: Admissão | U3: 1
B4: 2 | C4: LEANDRO PINHEIRO DOS SANTO | D4: ADM | E4: 44599 | L4: 0 | N4: 0 | Q4: 0 | T4: Demissão | U4: 0
B5: 9 | C5: SAMUEL APOLINÁRIO | D5: ADM | E5: 45702 | L5: 0 | N5: 0 | Q5: 0 | T5: Fim Colab | U5: =U2+U3-U4 -> 5
B6: 11 | C6: SILVANIA BARBOSA ALVES | D6: ADM | E6: 45736 | L6: 0 | N6: 0 | Q6: 0
B7: 10 | C7: VINICIUS ABRAO SACRAMENTO | D7: ADM | E7: 45734 | L7: 0 | N7: 0 | Q7: 0 | T7: Sócio | U7: 2
L8: =SUM(L4:L5) -> 0 | N8: =SUM(N4:N5) -> 0 | Q8: =SUM(Q4:Q5) -> 0 | T8: Total | U8: =U5+U7 -> 7
T10: Afastamentos
T11: Atestados | U11: 0
T12: Faltas | U12: =N8 -> 0
T14: Férias | U14: =Q8 -> 0
T15: Colaboradores | U15: 0
T17: Dias Úteis | U17: 23

Sheet Outubro 2025
H1: Atestados | M1: Faltas | O1: Férias
B2: Funcionário | C2: Nome do Funcionário | D2: Departamento | E2: Admissão | F2: Demissão | G2: Afastamento | H2: Início | I2: Fim | J2: Início | K2: Fim | L2: Dias | M2: Faltas | N2: Dias | O2: Início | P2: Fim | Q2: Dias | R2: Observação | T2: Início Colab | U2: 4
B3: 2 | C3: LEANDRO PINHEIRO DOS SANTO | D3: ADM | E3: 44599 | L3: 0 | N3: 0 | Q3: 0 | T3: Admissão | U3: 1
B4: 9 | C4: SAMUEL APOLINÁRIO | D4: ADM | E4: 45702 | L4: 0 | N4: 0 | Q4: 0 | T4: Demissão | U4: 1
B5: 11 | C5: SILVANIA BARBOSA ALVES | D5: ADM | E5: 45736 | L5: 0 | N5: 0 | Q5: 0 | T5: Fim Colab | U5: =U2+U3-U4 -> 4
B6: 11 | C6: TATIANI | D6: ADM | E6: 45964 | L6: 0 | N6: 0 | Q6: 0
B7: 10 | C7: VINICIUS ABRAO SACRAMENTO | D7: ADM | E7: 45734 | F7: 45975 | L7: 0 | N7: 0 | Q7: 0
L8: =SUM(L3:L4) -> 0 | N8: =SUM(N3:N4) -> 0 | Q8: =SUM(Q3:Q4) -> 0 | T8: Sócio | U8: 2
T9: Total | U9: =U5+U8 -> 6
T11: Afastamentos
T12: Atestados | U12: 0
T13: Faltas | U13: =N8 -> 0
T15: Férias | U15: =Q8 -> 0
T16: Colaboradores | U16: 11
T18: Dias Úteis | U18: 21

Sheet Novembro 25
H1: Atestados | M1: Faltas | O1: Férias
B2: Funcionário | C2: Nome do Funcionário | D2: Departamento | E2: Admissão | F2: Demissão | G2: Afastamento | H2: Início | I2: Fim | J2: Início | K2: Fim | L2: Dias | M2: Faltas | N2: Dias | O2: Início | P2: Fim | Q2: Dias | R2: Observação | T2: Início Colab | U2: 4
B3: 2 | C3: LEANDRO PINHEIRO DOS SANTO | D3: ADM | E3: 44599 | L3: 0 | N3: 0 | Q3: 0 | T3: Admissão | U3: 1
B4: 9 | C4: SAMUEL APOLINÁRIO | D4: ADM | E4: 45702 | L4: 0 | N4: 0 | Q4: 0 | T4: Demissão | U4: 2
B5: 11 | C5: SILVANIA BARBOSA ALVES | D5: ADM | E5: 45736 | L5: 0 | N5: 0 | Q5: 0 | T5: Fim Colab | U5: =U2+U3-U4 -> 3
B6: 11 | C6: TATIANI | D6: ADM | E6: 45964 | F6: 46373 | L6: 0 | N6: 0 | Q6: 0
B7: 10 | C7: VIVIANE DA COSTA | D7: ADM | E7: 46364 | F7: 46371 | L7: 0 | N7: 0 | Q7: 0
L8: =SUM(L3:L4) -> 0 | N8: =SUM(N3:N4) -> 0 | Q8: =SUM(Q3:Q4) -> 0 | T8: Sócio | U8: 2
T9: Total | U9: =U5+U8 -> 5
T11: Afastamentos
T12: Atestados | U12: 0
T13: Faltas | U13: =N8 -> 0
T15: Férias | U15: =Q8 -> 0
T16: Colaboradores | U16: 0
T18: Dias Úteis | U18: 22

Sheet Janeiro 26
H1: Atestados | M1: Faltas | O1: Férias
B2: Funcionário | C2: Nome do Funcionário | D2: Departamento | E2: Admissão | F2: Demissão | G2: Afastamento | H2: Início | I2: Fim | J2: Início | K2: Fim | L2: Dias | M2: Faltas | N2: Dias | O2: Início | P2: Fim | Q2: Dias | R2: Observação | T2: Início Colab | U2: 3
B3: 2 | C3: LEANDRO PINHEIRO DOS SANTO | D3: ADM | E3: 44599 | L3: 0 | N3: 0 | Q3: 0 | T3: Admissão | U3: 1
B4: 9 | C4: SAMUEL APOLINÁRIO | D4: ADM | E4: 45702 | L4: 0 | N4: 0 | Q4: 0 | T4: Demissão | U4: 0
B5: 11 | C5: SILVANIA BARBOSA ALVES | D5: ADM | E5: 45736 | L5: 0 | N5: 0 | Q5: 0 | T5: Fim Colab | U5: =U2+U3-U4 -> 4
B6: 11 | C6: MANOELA SILVA | D6: ADM | E6: 46043 | L6: 0 | N6: 0 | Q6: 0
L7: =SUM(L3:L4) -> 0 | N7: =SUM(N3:N4) -> 0 | Q7: =SUM(Q3:Q4) -> 0
T8: Sócio | U8: 2
T9: Total | U9: =U5+U8 -> 6
T11: Afastamentos
T12: Atestados | U12: 0
T13: Faltas | U13: =N7 -> 0
T15: Férias | U15: =Q7 -> 0
T16: Colaboradores | U16: 0
T18: Dias Úteis | U18: 21

Sheet Fevereiro 26
H1: Atestados | M1: Faltas | O1: Férias
B2: Funcionário | C2: Nome do Funcionário | D2: Departamento | E2: Admissão | F2: Demissão | G2: Afastamento | H2: Início | I2: Fim | J2: Início | K2: Fim | L2: Dias | M2: Faltas | N2: Dias | O2: Início | P2: Fim | Q2: Dias | R2: Observação | T2: Início Colab | U2: 4
B3: 13 | C3: FELIPE ROCHA | D3: ADM | E3: 46055 | L3: 0 | N3: 0 | Q3: 0 | T3: Admissão | U3: 2
B4: 14 | C4: HENRIQUE CAZEDEI | D4: ADM | E4: 46055 | L4: 0 | N4: 0 | Q4: 0 | T4: Demissão | U4: 0
B5: 2 | C5: LEANDRO PINHEIRO DOS SANTO | D5: ADM | E5: 44599 | L5: 0 | N5: 0 | Q5: 0 | T5: Fim Colab | U5: =U2+U3-U4 -> 6
B6: 9 | C6: SAMUEL APOLINÁRIO | D6: ADM | E6: 45702 | L6: 0 | N6: 0 | Q6: 0
B7: 11 | C7: SILVANIA BARBOSA ALVES | D7: ADM | E7: 45736 | L7: 0 | N7: 0 | Q7: 0
B8: 12 | C8: MANOELA SILVA | D8: ADM | E8: 46043 | L8: 0 | N8: 0 | Q8: 0 | T8: Sócio | U8: 2
L9: =SUM(L5:L6) -> 0 | N9: =SUM(N5:N6) -> 0 | Q9: =SUM(Q5:Q6) -> 0 | T9: Total | U9: =U5+U8 -> 8
T11: Afastamentos
T12: Atestados | U12: 0
T13: Faltas | U13: =N9 -> 0
T15: Férias | U15: =Q9 -> 0
T16: Colaboradores | U16: 0
T18: Dias Úteis | U18: 20

Sheet ADM_Movimentações
B2: Funcionário | C2: Nome do Funcionário | D2: Departamento | E2: Admissão | F2: Demissão | G2: Afastamento | H2: Dias | I2: Faltas | J2: Dias | K2: Férias | L2: Dias | N2: Início Colab. | O2: 3 | Q2: Admissão | R2: =E9 -> 1 | T2: Faltas | U2: =J9 -> 13 | Y2: Janeiro 2026 | AE2: D. Produtivo | AF2: =(U8-U3-U2-R5) -> 60.5
B3: 2 | C3: LEANDRO PINHEIRO DOS SANTO | D3: ADM | H3: 0 | J3: 0 | L3: 0 | Q3: Demissão | R3: =F9 -> 0 | T3: Férias | U3: =L9 -> 0 | W3: Dom | X3: Seg | Y3: Ter | Z3: Qua | AA3: Qui | AB3: Sex | AC3: Sáb | AE3: D. N. Produt. | AF3: =U8-AF2 -> 13
B4: 9 | C4: SAMUEL APOLINÁRIO | D4: ADM | H4: 0 | J4: 0 | L4: 0 | Q4: Fim Colab | R4: =O2+R2-R3 -> 4 | T4: Colaboradores | U4: =K9 -> 0 | AA4: 46023 | AB4: 46024 | AC4: 46025 | AE4: Horas Program. | AF4: =(R4*8.8)*R7 -> 739.2
B5: 11 | C5: SILVANIA BARBOSA ALVES | D5: ADM | H5: 0 | J5: 0 | L5: 0 | Q5: Afastam. | R5: =H9 -> 0 | W5: 46026 | X5: 46027 | Y5: 46028 | Z5: 46029 | AA5: 46030 | AB5: 46031 | AC5: 46032 | AE5: H. N. Produtiva | AF5: =AF3*8.8 -> 114.4
B6: 11 | C6: MANOELA SILVA | D6: ADM | E6: 46043 | H6: 0 | I6: 01 a 20 | J6: 13 | L6: 0 | W6: 46033 | X6: 46034 | Y6: 46035 | Z6: 46036 | AA6: 46037 | AB6: 46038 | AC6: 46039 | AE6: Efetivo Pessoal | AF6: =(AF4-AF5)/(8.8*R7) -> 3.3809524
